
2022-06-01 12:15:19,373 INFO: errors [in C:\Users\1\Desktop\Udacity\Fyyur Project\app.py:729]
2022-06-01 12:16:12,711 ERROR: Exception on /artists [GET] [in C:\Users\1\Desktop\Udacity\Fyyur Project\env\lib\site-packages\flask\app.py:1455]
Traceback (most recent call last):
  File "C:\Users\1\Desktop\Udacity\Fyyur Project\env\lib\site-packages\sqlalchemy\engine\base.py", line 3280, in _wrap_pool_connect
    return fn()
  File "C:\Users\1\Desktop\Udacity\Fyyur Project\env\lib\site-packages\sqlalchemy\pool\base.py", line 310, in connect
    return _ConnectionFairy._checkout(self)
  File "C:\Users\1\Desktop\Udacity\Fyyur Project\env\lib\site-packages\sqlalchemy\pool\base.py", line 868, in _checkout
    fairy = _ConnectionRecord.checkout(pool)
  File "C:\Users\1\Desktop\Udacity\Fyyur Project\env\lib\site-packages\sqlalchemy\pool\base.py", line 476, in checkout
    rec = pool._do_get()
  File "C:\Users\1\Desktop\Udacity\Fyyur Project\env\lib\site-packages\sqlalchemy\pool\impl.py", line 145, in _do_get
    with util.safe_reraise():
  File "C:\Users\1\Desktop\Udacity\Fyyur Project\env\lib\site-packages\sqlalchemy\util\langhelpers.py", line 70, in __exit__
    compat.raise_(
  File "C:\Users\1\Desktop\Udacity\Fyyur Project\env\lib\site-packages\sqlalchemy\util\compat.py", line 207, in raise_
    raise exception
  File "C:\Users\1\Desktop\Udacity\Fyyur Project\env\lib\site-packages\sqlalchemy\pool\impl.py", line 143, in _do_get
    return self._create_connection()
  File "C:\Users\1\Desktop\Udacity\Fyyur Project\env\lib\site-packages\sqlalchemy\pool\base.py", line 256, in _create_connection
    return _ConnectionRecord(self)
  File "C:\Users\1\Desktop\Udacity\Fyyur Project\env\lib\site-packages\sqlalchemy\pool\base.py", line 371, in __init__
    self.__connect()
  File "C:\Users\1\Desktop\Udacity\Fyyur Project\env\lib\site-packages\sqlalchemy\pool\base.py", line 665, in __connect
    with util.safe_reraise():
  File "C:\Users\1\Desktop\Udacity\Fyyur Project\env\lib\site-packages\sqlalchemy\util\langhelpers.py", line 70, in __exit__
    compat.raise_(
  File "C:\Users\1\Desktop\Udacity\Fyyur Project\env\lib\site-packages\sqlalchemy\util\compat.py", line 207, in raise_
    raise exception
  File "C:\Users\1\Desktop\Udacity\Fyyur Project\env\lib\site-packages\sqlalchemy\pool\base.py", line 661, in __connect
    self.dbapi_connection = connection = pool._invoke_creator(self)
  File "C:\Users\1\Desktop\Udacity\Fyyur Project\env\lib\site-packages\sqlalchemy\engine\create.py", line 590, in connect
    return dialect.connect(*cargs, **cparams)
  File "C:\Users\1\Desktop\Udacity\Fyyur Project\env\lib\site-packages\sqlalchemy\engine\default.py", line 597, in connect
    return self.dbapi.connect(*cargs, **cparams)
  File "C:\Users\1\Desktop\Udacity\Fyyur Project\env\lib\site-packages\psycopg2\__init__.py", line 122, in connect
    conn = _connect(dsn, connection_factory=connection_factory, **kwasync)
psycopg2.OperationalError: connection to server at "localhost" (::1), port 5432 failed: FATAL:  database "Fyyur" does not exist


The above exception was the direct cause of the following exception:

Traceback (most recent call last):
  File "C:\Users\1\Desktop\Udacity\Fyyur Project\env\lib\site-packages\flask\app.py", line 2077, in wsgi_app
    response = self.full_dispatch_request()
  File "C:\Users\1\Desktop\Udacity\Fyyur Project\env\lib\site-packages\flask\app.py", line 1525, in full_dispatch_request
    rv = self.handle_user_exception(e)
  File "C:\Users\1\Desktop\Udacity\Fyyur Project\env\lib\site-packages\flask\app.py", line 1523, in full_dispatch_request
    rv = self.dispatch_request()
  File "C:\Users\1\Desktop\Udacity\Fyyur Project\env\lib\site-packages\flask\app.py", line 1509, in dispatch_request
    return self.ensure_sync(self.view_functions[rule.endpoint])(**req.view_args)
  File "C:\Users\1\Desktop\Udacity\Fyyur Project\app.py", line 386, in artists
    artists = Artist.query.order_by("id").all()
  File "C:\Users\1\Desktop\Udacity\Fyyur Project\env\lib\site-packages\sqlalchemy\orm\query.py", line 2768, in all
    return self._iter().all()
  File "C:\Users\1\Desktop\Udacity\Fyyur Project\env\lib\site-packages\sqlalchemy\orm\query.py", line 2903, in _iter
    result = self.session.execute(
  File "C:\Users\1\Desktop\Udacity\Fyyur Project\env\lib\site-packages\sqlalchemy\orm\session.py", line 1695, in execute
    conn = self._connection_for_bind(bind)
  File "C:\Users\1\Desktop\Udacity\Fyyur Project\env\lib\site-packages\sqlalchemy\orm\session.py", line 1536, in _connection_for_bind
    return self._transaction._connection_for_bind(
  File "C:\Users\1\Desktop\Udacity\Fyyur Project\env\lib\site-packages\sqlalchemy\orm\session.py", line 747, in _connection_for_bind
    conn = bind.connect()
  File "C:\Users\1\Desktop\Udacity\Fyyur Project\env\lib\site-packages\sqlalchemy\engine\base.py", line 3234, in connect
    return self._connection_cls(self, close_with_result=close_with_result)
  File "C:\Users\1\Desktop\Udacity\Fyyur Project\env\lib\site-packages\sqlalchemy\engine\base.py", line 96, in __init__
    else engine.raw_connection()
  File "C:\Users\1\Desktop\Udacity\Fyyur Project\env\lib\site-packages\sqlalchemy\engine\base.py", line 3313, in raw_connection
    return self._wrap_pool_connect(self.pool.connect, _connection)
  File "C:\Users\1\Desktop\Udacity\Fyyur Project\env\lib\site-packages\sqlalchemy\engine\base.py", line 3283, in _wrap_pool_connect
    Connection._handle_dbapi_exception_noconnection(
  File "C:\Users\1\Desktop\Udacity\Fyyur Project\env\lib\site-packages\sqlalchemy\engine\base.py", line 2117, in _handle_dbapi_exception_noconnection
    util.raise_(
  File "C:\Users\1\Desktop\Udacity\Fyyur Project\env\lib\site-packages\sqlalchemy\util\compat.py", line 207, in raise_
    raise exception
  File "C:\Users\1\Desktop\Udacity\Fyyur Project\env\lib\site-packages\sqlalchemy\engine\base.py", line 3280, in _wrap_pool_connect
    return fn()
  File "C:\Users\1\Desktop\Udacity\Fyyur Project\env\lib\site-packages\sqlalchemy\pool\base.py", line 310, in connect
    return _ConnectionFairy._checkout(self)
  File "C:\Users\1\Desktop\Udacity\Fyyur Project\env\lib\site-packages\sqlalchemy\pool\base.py", line 868, in _checkout
    fairy = _ConnectionRecord.checkout(pool)
  File "C:\Users\1\Desktop\Udacity\Fyyur Project\env\lib\site-packages\sqlalchemy\pool\base.py", line 476, in checkout
    rec = pool._do_get()
  File "C:\Users\1\Desktop\Udacity\Fyyur Project\env\lib\site-packages\sqlalchemy\pool\impl.py", line 145, in _do_get
    with util.safe_reraise():
  File "C:\Users\1\Desktop\Udacity\Fyyur Project\env\lib\site-packages\sqlalchemy\util\langhelpers.py", line 70, in __exit__
    compat.raise_(
  File "C:\Users\1\Desktop\Udacity\Fyyur Project\env\lib\site-packages\sqlalchemy\util\compat.py", line 207, in raise_
    raise exception
  File "C:\Users\1\Desktop\Udacity\Fyyur Project\env\lib\site-packages\sqlalchemy\pool\impl.py", line 143, in _do_get
    return self._create_connection()
  File "C:\Users\1\Desktop\Udacity\Fyyur Project\env\lib\site-packages\sqlalchemy\pool\base.py", line 256, in _create_connection
    return _ConnectionRecord(self)
  File "C:\Users\1\Desktop\Udacity\Fyyur Project\env\lib\site-packages\sqlalchemy\pool\base.py", line 371, in __init__
    self.__connect()
  File "C:\Users\1\Desktop\Udacity\Fyyur Project\env\lib\site-packages\sqlalchemy\pool\base.py", line 665, in __connect
    with util.safe_reraise():
  File "C:\Users\1\Desktop\Udacity\Fyyur Project\env\lib\site-packages\sqlalchemy\util\langhelpers.py", line 70, in __exit__
    compat.raise_(
  File "C:\Users\1\Desktop\Udacity\Fyyur Project\env\lib\site-packages\sqlalchemy\util\compat.py", line 207, in raise_
    raise exception
  File "C:\Users\1\Desktop\Udacity\Fyyur Project\env\lib\site-packages\sqlalchemy\pool\base.py", line 661, in __connect
    self.dbapi_connection = connection = pool._invoke_creator(self)
  File "C:\Users\1\Desktop\Udacity\Fyyur Project\env\lib\site-packages\sqlalchemy\engine\create.py", line 590, in connect
    return dialect.connect(*cargs, **cparams)
  File "C:\Users\1\Desktop\Udacity\Fyyur Project\env\lib\site-packages\sqlalchemy\engine\default.py", line 597, in connect
    return self.dbapi.connect(*cargs, **cparams)
  File "C:\Users\1\Desktop\Udacity\Fyyur Project\env\lib\site-packages\psycopg2\__init__.py", line 122, in connect
    conn = _connect(dsn, connection_factory=connection_factory, **kwasync)
sqlalchemy.exc.OperationalError: (psycopg2.OperationalError) connection to server at "localhost" (::1), port 5432 failed: FATAL:  database "Fyyur" does not exist

(Background on this error at: https://sqlalche.me/e/14/e3q8)
2022-06-01 12:16:28,707 ERROR: Exception on /venues [GET] [in C:\Users\1\Desktop\Udacity\Fyyur Project\env\lib\site-packages\flask\app.py:1455]
Traceback (most recent call last):
  File "C:\Users\1\Desktop\Udacity\Fyyur Project\env\lib\site-packages\sqlalchemy\engine\base.py", line 3280, in _wrap_pool_connect
    return fn()
  File "C:\Users\1\Desktop\Udacity\Fyyur Project\env\lib\site-packages\sqlalchemy\pool\base.py", line 310, in connect
    return _ConnectionFairy._checkout(self)
  File "C:\Users\1\Desktop\Udacity\Fyyur Project\env\lib\site-packages\sqlalchemy\pool\base.py", line 868, in _checkout
    fairy = _ConnectionRecord.checkout(pool)
  File "C:\Users\1\Desktop\Udacity\Fyyur Project\env\lib\site-packages\sqlalchemy\pool\base.py", line 476, in checkout
    rec = pool._do_get()
  File "C:\Users\1\Desktop\Udacity\Fyyur Project\env\lib\site-packages\sqlalchemy\pool\impl.py", line 145, in _do_get
    with util.safe_reraise():
  File "C:\Users\1\Desktop\Udacity\Fyyur Project\env\lib\site-packages\sqlalchemy\util\langhelpers.py", line 70, in __exit__
    compat.raise_(
  File "C:\Users\1\Desktop\Udacity\Fyyur Project\env\lib\site-packages\sqlalchemy\util\compat.py", line 207, in raise_
    raise exception
  File "C:\Users\1\Desktop\Udacity\Fyyur Project\env\lib\site-packages\sqlalchemy\pool\impl.py", line 143, in _do_get
    return self._create_connection()
  File "C:\Users\1\Desktop\Udacity\Fyyur Project\env\lib\site-packages\sqlalchemy\pool\base.py", line 256, in _create_connection
    return _ConnectionRecord(self)
  File "C:\Users\1\Desktop\Udacity\Fyyur Project\env\lib\site-packages\sqlalchemy\pool\base.py", line 371, in __init__
    self.__connect()
  File "C:\Users\1\Desktop\Udacity\Fyyur Project\env\lib\site-packages\sqlalchemy\pool\base.py", line 665, in __connect
    with util.safe_reraise():
  File "C:\Users\1\Desktop\Udacity\Fyyur Project\env\lib\site-packages\sqlalchemy\util\langhelpers.py", line 70, in __exit__
    compat.raise_(
  File "C:\Users\1\Desktop\Udacity\Fyyur Project\env\lib\site-packages\sqlalchemy\util\compat.py", line 207, in raise_
    raise exception
  File "C:\Users\1\Desktop\Udacity\Fyyur Project\env\lib\site-packages\sqlalchemy\pool\base.py", line 661, in __connect
    self.dbapi_connection = connection = pool._invoke_creator(self)
  File "C:\Users\1\Desktop\Udacity\Fyyur Project\env\lib\site-packages\sqlalchemy\engine\create.py", line 590, in connect
    return dialect.connect(*cargs, **cparams)
  File "C:\Users\1\Desktop\Udacity\Fyyur Project\env\lib\site-packages\sqlalchemy\engine\default.py", line 597, in connect
    return self.dbapi.connect(*cargs, **cparams)
  File "C:\Users\1\Desktop\Udacity\Fyyur Project\env\lib\site-packages\psycopg2\__init__.py", line 122, in connect
    conn = _connect(dsn, connection_factory=connection_factory, **kwasync)
psycopg2.OperationalError: connection to server at "localhost" (::1), port 5432 failed: FATAL:  database "Fyyur" does not exist


The above exception was the direct cause of the following exception:

Traceback (most recent call last):
  File "C:\Users\1\Desktop\Udacity\Fyyur Project\env\lib\site-packages\flask\app.py", line 2077, in wsgi_app
    response = self.full_dispatch_request()
  File "C:\Users\1\Desktop\Udacity\Fyyur Project\env\lib\site-packages\flask\app.py", line 1525, in full_dispatch_request
    rv = self.handle_user_exception(e)
  File "C:\Users\1\Desktop\Udacity\Fyyur Project\env\lib\site-packages\flask\app.py", line 1523, in full_dispatch_request
    rv = self.dispatch_request()
  File "C:\Users\1\Desktop\Udacity\Fyyur Project\env\lib\site-packages\flask\app.py", line 1509, in dispatch_request
    return self.ensure_sync(self.view_functions[rule.endpoint])(**req.view_args)
  File "C:\Users\1\Desktop\Udacity\Fyyur Project\app.py", line 180, in venues
    .all()
  File "C:\Users\1\Desktop\Udacity\Fyyur Project\env\lib\site-packages\sqlalchemy\orm\query.py", line 2768, in all
    return self._iter().all()
  File "C:\Users\1\Desktop\Udacity\Fyyur Project\env\lib\site-packages\sqlalchemy\orm\query.py", line 2903, in _iter
    result = self.session.execute(
  File "C:\Users\1\Desktop\Udacity\Fyyur Project\env\lib\site-packages\sqlalchemy\orm\session.py", line 1695, in execute
    conn = self._connection_for_bind(bind)
  File "C:\Users\1\Desktop\Udacity\Fyyur Project\env\lib\site-packages\sqlalchemy\orm\session.py", line 1536, in _connection_for_bind
    return self._transaction._connection_for_bind(
  File "C:\Users\1\Desktop\Udacity\Fyyur Project\env\lib\site-packages\sqlalchemy\orm\session.py", line 747, in _connection_for_bind
    conn = bind.connect()
  File "C:\Users\1\Desktop\Udacity\Fyyur Project\env\lib\site-packages\sqlalchemy\engine\base.py", line 3234, in connect
    return self._connection_cls(self, close_with_result=close_with_result)
  File "C:\Users\1\Desktop\Udacity\Fyyur Project\env\lib\site-packages\sqlalchemy\engine\base.py", line 96, in __init__
    else engine.raw_connection()
  File "C:\Users\1\Desktop\Udacity\Fyyur Project\env\lib\site-packages\sqlalchemy\engine\base.py", line 3313, in raw_connection
    return self._wrap_pool_connect(self.pool.connect, _connection)
  File "C:\Users\1\Desktop\Udacity\Fyyur Project\env\lib\site-packages\sqlalchemy\engine\base.py", line 3283, in _wrap_pool_connect
    Connection._handle_dbapi_exception_noconnection(
  File "C:\Users\1\Desktop\Udacity\Fyyur Project\env\lib\site-packages\sqlalchemy\engine\base.py", line 2117, in _handle_dbapi_exception_noconnection
    util.raise_(
  File "C:\Users\1\Desktop\Udacity\Fyyur Project\env\lib\site-packages\sqlalchemy\util\compat.py", line 207, in raise_
    raise exception
  File "C:\Users\1\Desktop\Udacity\Fyyur Project\env\lib\site-packages\sqlalchemy\engine\base.py", line 3280, in _wrap_pool_connect
    return fn()
  File "C:\Users\1\Desktop\Udacity\Fyyur Project\env\lib\site-packages\sqlalchemy\pool\base.py", line 310, in connect
    return _ConnectionFairy._checkout(self)
  File "C:\Users\1\Desktop\Udacity\Fyyur Project\env\lib\site-packages\sqlalchemy\pool\base.py", line 868, in _checkout
    fairy = _ConnectionRecord.checkout(pool)
  File "C:\Users\1\Desktop\Udacity\Fyyur Project\env\lib\site-packages\sqlalchemy\pool\base.py", line 476, in checkout
    rec = pool._do_get()
  File "C:\Users\1\Desktop\Udacity\Fyyur Project\env\lib\site-packages\sqlalchemy\pool\impl.py", line 145, in _do_get
    with util.safe_reraise():
  File "C:\Users\1\Desktop\Udacity\Fyyur Project\env\lib\site-packages\sqlalchemy\util\langhelpers.py", line 70, in __exit__
    compat.raise_(
  File "C:\Users\1\Desktop\Udacity\Fyyur Project\env\lib\site-packages\sqlalchemy\util\compat.py", line 207, in raise_
    raise exception
  File "C:\Users\1\Desktop\Udacity\Fyyur Project\env\lib\site-packages\sqlalchemy\pool\impl.py", line 143, in _do_get
    return self._create_connection()
  File "C:\Users\1\Desktop\Udacity\Fyyur Project\env\lib\site-packages\sqlalchemy\pool\base.py", line 256, in _create_connection
    return _ConnectionRecord(self)
  File "C:\Users\1\Desktop\Udacity\Fyyur Project\env\lib\site-packages\sqlalchemy\pool\base.py", line 371, in __init__
    self.__connect()
  File "C:\Users\1\Desktop\Udacity\Fyyur Project\env\lib\site-packages\sqlalchemy\pool\base.py", line 665, in __connect
    with util.safe_reraise():
  File "C:\Users\1\Desktop\Udacity\Fyyur Project\env\lib\site-packages\sqlalchemy\util\langhelpers.py", line 70, in __exit__
    compat.raise_(
  File "C:\Users\1\Desktop\Udacity\Fyyur Project\env\lib\site-packages\sqlalchemy\util\compat.py", line 207, in raise_
    raise exception
  File "C:\Users\1\Desktop\Udacity\Fyyur Project\env\lib\site-packages\sqlalchemy\pool\base.py", line 661, in __connect
    self.dbapi_connection = connection = pool._invoke_creator(self)
  File "C:\Users\1\Desktop\Udacity\Fyyur Project\env\lib\site-packages\sqlalchemy\engine\create.py", line 590, in connect
    return dialect.connect(*cargs, **cparams)
  File "C:\Users\1\Desktop\Udacity\Fyyur Project\env\lib\site-packages\sqlalchemy\engine\default.py", line 597, in connect
    return self.dbapi.connect(*cargs, **cparams)
  File "C:\Users\1\Desktop\Udacity\Fyyur Project\env\lib\site-packages\psycopg2\__init__.py", line 122, in connect
    conn = _connect(dsn, connection_factory=connection_factory, **kwasync)
sqlalchemy.exc.OperationalError: (psycopg2.OperationalError) connection to server at "localhost" (::1), port 5432 failed: FATAL:  database "Fyyur" does not exist

(Background on this error at: https://sqlalche.me/e/14/e3q8)
2022-06-01 12:16:33,060 ERROR: Exception on /shows [GET] [in C:\Users\1\Desktop\Udacity\Fyyur Project\env\lib\site-packages\flask\app.py:1455]
Traceback (most recent call last):
  File "C:\Users\1\Desktop\Udacity\Fyyur Project\env\lib\site-packages\sqlalchemy\engine\base.py", line 3280, in _wrap_pool_connect
    return fn()
  File "C:\Users\1\Desktop\Udacity\Fyyur Project\env\lib\site-packages\sqlalchemy\pool\base.py", line 310, in connect
    return _ConnectionFairy._checkout(self)
  File "C:\Users\1\Desktop\Udacity\Fyyur Project\env\lib\site-packages\sqlalchemy\pool\base.py", line 868, in _checkout
    fairy = _ConnectionRecord.checkout(pool)
  File "C:\Users\1\Desktop\Udacity\Fyyur Project\env\lib\site-packages\sqlalchemy\pool\base.py", line 476, in checkout
    rec = pool._do_get()
  File "C:\Users\1\Desktop\Udacity\Fyyur Project\env\lib\site-packages\sqlalchemy\pool\impl.py", line 145, in _do_get
    with util.safe_reraise():
  File "C:\Users\1\Desktop\Udacity\Fyyur Project\env\lib\site-packages\sqlalchemy\util\langhelpers.py", line 70, in __exit__
    compat.raise_(
  File "C:\Users\1\Desktop\Udacity\Fyyur Project\env\lib\site-packages\sqlalchemy\util\compat.py", line 207, in raise_
    raise exception
  File "C:\Users\1\Desktop\Udacity\Fyyur Project\env\lib\site-packages\sqlalchemy\pool\impl.py", line 143, in _do_get
    return self._create_connection()
  File "C:\Users\1\Desktop\Udacity\Fyyur Project\env\lib\site-packages\sqlalchemy\pool\base.py", line 256, in _create_connection
    return _ConnectionRecord(self)
  File "C:\Users\1\Desktop\Udacity\Fyyur Project\env\lib\site-packages\sqlalchemy\pool\base.py", line 371, in __init__
    self.__connect()
  File "C:\Users\1\Desktop\Udacity\Fyyur Project\env\lib\site-packages\sqlalchemy\pool\base.py", line 665, in __connect
    with util.safe_reraise():
  File "C:\Users\1\Desktop\Udacity\Fyyur Project\env\lib\site-packages\sqlalchemy\util\langhelpers.py", line 70, in __exit__
    compat.raise_(
  File "C:\Users\1\Desktop\Udacity\Fyyur Project\env\lib\site-packages\sqlalchemy\util\compat.py", line 207, in raise_
    raise exception
  File "C:\Users\1\Desktop\Udacity\Fyyur Project\env\lib\site-packages\sqlalchemy\pool\base.py", line 661, in __connect
    self.dbapi_connection = connection = pool._invoke_creator(self)
  File "C:\Users\1\Desktop\Udacity\Fyyur Project\env\lib\site-packages\sqlalchemy\engine\create.py", line 590, in connect
    return dialect.connect(*cargs, **cparams)
  File "C:\Users\1\Desktop\Udacity\Fyyur Project\env\lib\site-packages\sqlalchemy\engine\default.py", line 597, in connect
    return self.dbapi.connect(*cargs, **cparams)
  File "C:\Users\1\Desktop\Udacity\Fyyur Project\env\lib\site-packages\psycopg2\__init__.py", line 122, in connect
    conn = _connect(dsn, connection_factory=connection_factory, **kwasync)
psycopg2.OperationalError: connection to server at "localhost" (::1), port 5432 failed: FATAL:  database "Fyyur" does not exist


The above exception was the direct cause of the following exception:

Traceback (most recent call last):
  File "C:\Users\1\Desktop\Udacity\Fyyur Project\env\lib\site-packages\flask\app.py", line 2077, in wsgi_app
    response = self.full_dispatch_request()
  File "C:\Users\1\Desktop\Udacity\Fyyur Project\env\lib\site-packages\flask\app.py", line 1525, in full_dispatch_request
    rv = self.handle_user_exception(e)
  File "C:\Users\1\Desktop\Udacity\Fyyur Project\env\lib\site-packages\flask\app.py", line 1523, in full_dispatch_request
    rv = self.dispatch_request()
  File "C:\Users\1\Desktop\Udacity\Fyyur Project\env\lib\site-packages\flask\app.py", line 1509, in dispatch_request
    return self.ensure_sync(self.view_functions[rule.endpoint])(**req.view_args)
  File "C:\Users\1\Desktop\Udacity\Fyyur Project\app.py", line 665, in shows
    for show in db.session.query(Show).join(Artist).join(Venue).all():
  File "C:\Users\1\Desktop\Udacity\Fyyur Project\env\lib\site-packages\sqlalchemy\orm\query.py", line 2768, in all
    return self._iter().all()
  File "C:\Users\1\Desktop\Udacity\Fyyur Project\env\lib\site-packages\sqlalchemy\orm\query.py", line 2903, in _iter
    result = self.session.execute(
  File "C:\Users\1\Desktop\Udacity\Fyyur Project\env\lib\site-packages\sqlalchemy\orm\session.py", line 1695, in execute
    conn = self._connection_for_bind(bind)
  File "C:\Users\1\Desktop\Udacity\Fyyur Project\env\lib\site-packages\sqlalchemy\orm\session.py", line 1536, in _connection_for_bind
    return self._transaction._connection_for_bind(
  File "C:\Users\1\Desktop\Udacity\Fyyur Project\env\lib\site-packages\sqlalchemy\orm\session.py", line 747, in _connection_for_bind
    conn = bind.connect()
  File "C:\Users\1\Desktop\Udacity\Fyyur Project\env\lib\site-packages\sqlalchemy\engine\base.py", line 3234, in connect
    return self._connection_cls(self, close_with_result=close_with_result)
  File "C:\Users\1\Desktop\Udacity\Fyyur Project\env\lib\site-packages\sqlalchemy\engine\base.py", line 96, in __init__
    else engine.raw_connection()
  File "C:\Users\1\Desktop\Udacity\Fyyur Project\env\lib\site-packages\sqlalchemy\engine\base.py", line 3313, in raw_connection
    return self._wrap_pool_connect(self.pool.connect, _connection)
  File "C:\Users\1\Desktop\Udacity\Fyyur Project\env\lib\site-packages\sqlalchemy\engine\base.py", line 3283, in _wrap_pool_connect
    Connection._handle_dbapi_exception_noconnection(
  File "C:\Users\1\Desktop\Udacity\Fyyur Project\env\lib\site-packages\sqlalchemy\engine\base.py", line 2117, in _handle_dbapi_exception_noconnection
    util.raise_(
  File "C:\Users\1\Desktop\Udacity\Fyyur Project\env\lib\site-packages\sqlalchemy\util\compat.py", line 207, in raise_
    raise exception
  File "C:\Users\1\Desktop\Udacity\Fyyur Project\env\lib\site-packages\sqlalchemy\engine\base.py", line 3280, in _wrap_pool_connect
    return fn()
  File "C:\Users\1\Desktop\Udacity\Fyyur Project\env\lib\site-packages\sqlalchemy\pool\base.py", line 310, in connect
    return _ConnectionFairy._checkout(self)
  File "C:\Users\1\Desktop\Udacity\Fyyur Project\env\lib\site-packages\sqlalchemy\pool\base.py", line 868, in _checkout
    fairy = _ConnectionRecord.checkout(pool)
  File "C:\Users\1\Desktop\Udacity\Fyyur Project\env\lib\site-packages\sqlalchemy\pool\base.py", line 476, in checkout
    rec = pool._do_get()
  File "C:\Users\1\Desktop\Udacity\Fyyur Project\env\lib\site-packages\sqlalchemy\pool\impl.py", line 145, in _do_get
    with util.safe_reraise():
  File "C:\Users\1\Desktop\Udacity\Fyyur Project\env\lib\site-packages\sqlalchemy\util\langhelpers.py", line 70, in __exit__
    compat.raise_(
  File "C:\Users\1\Desktop\Udacity\Fyyur Project\env\lib\site-packages\sqlalchemy\util\compat.py", line 207, in raise_
    raise exception
  File "C:\Users\1\Desktop\Udacity\Fyyur Project\env\lib\site-packages\sqlalchemy\pool\impl.py", line 143, in _do_get
    return self._create_connection()
  File "C:\Users\1\Desktop\Udacity\Fyyur Project\env\lib\site-packages\sqlalchemy\pool\base.py", line 256, in _create_connection
    return _ConnectionRecord(self)
  File "C:\Users\1\Desktop\Udacity\Fyyur Project\env\lib\site-packages\sqlalchemy\pool\base.py", line 371, in __init__
    self.__connect()
  File "C:\Users\1\Desktop\Udacity\Fyyur Project\env\lib\site-packages\sqlalchemy\pool\base.py", line 665, in __connect
    with util.safe_reraise():
  File "C:\Users\1\Desktop\Udacity\Fyyur Project\env\lib\site-packages\sqlalchemy\util\langhelpers.py", line 70, in __exit__
    compat.raise_(
  File "C:\Users\1\Desktop\Udacity\Fyyur Project\env\lib\site-packages\sqlalchemy\util\compat.py", line 207, in raise_
    raise exception
  File "C:\Users\1\Desktop\Udacity\Fyyur Project\env\lib\site-packages\sqlalchemy\pool\base.py", line 661, in __connect
    self.dbapi_connection = connection = pool._invoke_creator(self)
  File "C:\Users\1\Desktop\Udacity\Fyyur Project\env\lib\site-packages\sqlalchemy\engine\create.py", line 590, in connect
    return dialect.connect(*cargs, **cparams)
  File "C:\Users\1\Desktop\Udacity\Fyyur Project\env\lib\site-packages\sqlalchemy\engine\default.py", line 597, in connect
    return self.dbapi.connect(*cargs, **cparams)
  File "C:\Users\1\Desktop\Udacity\Fyyur Project\env\lib\site-packages\psycopg2\__init__.py", line 122, in connect
    conn = _connect(dsn, connection_factory=connection_factory, **kwasync)
sqlalchemy.exc.OperationalError: (psycopg2.OperationalError) connection to server at "localhost" (::1), port 5432 failed: FATAL:  database "Fyyur" does not exist

(Background on this error at: https://sqlalche.me/e/14/e3q8)
2022-06-01 12:19:43,323 ERROR: Exception on /shows [GET] [in C:\Users\1\Desktop\Udacity\Fyyur Project\env\lib\site-packages\flask\app.py:1455]
Traceback (most recent call last):
  File "C:\Users\1\Desktop\Udacity\Fyyur Project\env\lib\site-packages\sqlalchemy\engine\base.py", line 3280, in _wrap_pool_connect
    return fn()
  File "C:\Users\1\Desktop\Udacity\Fyyur Project\env\lib\site-packages\sqlalchemy\pool\base.py", line 310, in connect
    return _ConnectionFairy._checkout(self)
  File "C:\Users\1\Desktop\Udacity\Fyyur Project\env\lib\site-packages\sqlalchemy\pool\base.py", line 868, in _checkout
    fairy = _ConnectionRecord.checkout(pool)
  File "C:\Users\1\Desktop\Udacity\Fyyur Project\env\lib\site-packages\sqlalchemy\pool\base.py", line 476, in checkout
    rec = pool._do_get()
  File "C:\Users\1\Desktop\Udacity\Fyyur Project\env\lib\site-packages\sqlalchemy\pool\impl.py", line 145, in _do_get
    with util.safe_reraise():
  File "C:\Users\1\Desktop\Udacity\Fyyur Project\env\lib\site-packages\sqlalchemy\util\langhelpers.py", line 70, in __exit__
    compat.raise_(
  File "C:\Users\1\Desktop\Udacity\Fyyur Project\env\lib\site-packages\sqlalchemy\util\compat.py", line 207, in raise_
    raise exception
  File "C:\Users\1\Desktop\Udacity\Fyyur Project\env\lib\site-packages\sqlalchemy\pool\impl.py", line 143, in _do_get
    return self._create_connection()
  File "C:\Users\1\Desktop\Udacity\Fyyur Project\env\lib\site-packages\sqlalchemy\pool\base.py", line 256, in _create_connection
    return _ConnectionRecord(self)
  File "C:\Users\1\Desktop\Udacity\Fyyur Project\env\lib\site-packages\sqlalchemy\pool\base.py", line 371, in __init__
    self.__connect()
  File "C:\Users\1\Desktop\Udacity\Fyyur Project\env\lib\site-packages\sqlalchemy\pool\base.py", line 665, in __connect
    with util.safe_reraise():
  File "C:\Users\1\Desktop\Udacity\Fyyur Project\env\lib\site-packages\sqlalchemy\util\langhelpers.py", line 70, in __exit__
    compat.raise_(
  File "C:\Users\1\Desktop\Udacity\Fyyur Project\env\lib\site-packages\sqlalchemy\util\compat.py", line 207, in raise_
    raise exception
  File "C:\Users\1\Desktop\Udacity\Fyyur Project\env\lib\site-packages\sqlalchemy\pool\base.py", line 661, in __connect
    self.dbapi_connection = connection = pool._invoke_creator(self)
  File "C:\Users\1\Desktop\Udacity\Fyyur Project\env\lib\site-packages\sqlalchemy\engine\create.py", line 590, in connect
    return dialect.connect(*cargs, **cparams)
  File "C:\Users\1\Desktop\Udacity\Fyyur Project\env\lib\site-packages\sqlalchemy\engine\default.py", line 597, in connect
    return self.dbapi.connect(*cargs, **cparams)
  File "C:\Users\1\Desktop\Udacity\Fyyur Project\env\lib\site-packages\psycopg2\__init__.py", line 122, in connect
    conn = _connect(dsn, connection_factory=connection_factory, **kwasync)
psycopg2.OperationalError: connection to server at "localhost" (::1), port 5432 failed: FATAL:  database "Fyyur" does not exist


The above exception was the direct cause of the following exception:

Traceback (most recent call last):
  File "C:\Users\1\Desktop\Udacity\Fyyur Project\env\lib\site-packages\flask\app.py", line 2077, in wsgi_app
    response = self.full_dispatch_request()
  File "C:\Users\1\Desktop\Udacity\Fyyur Project\env\lib\site-packages\flask\app.py", line 1525, in full_dispatch_request
    rv = self.handle_user_exception(e)
  File "C:\Users\1\Desktop\Udacity\Fyyur Project\env\lib\site-packages\flask\app.py", line 1523, in full_dispatch_request
    rv = self.dispatch_request()
  File "C:\Users\1\Desktop\Udacity\Fyyur Project\env\lib\site-packages\flask\app.py", line 1509, in dispatch_request
    return self.ensure_sync(self.view_functions[rule.endpoint])(**req.view_args)
  File "C:\Users\1\Desktop\Udacity\Fyyur Project\app.py", line 665, in shows
    for show in db.session.query(Show).join(Artist).join(Venue).all():
  File "C:\Users\1\Desktop\Udacity\Fyyur Project\env\lib\site-packages\sqlalchemy\orm\query.py", line 2768, in all
    return self._iter().all()
  File "C:\Users\1\Desktop\Udacity\Fyyur Project\env\lib\site-packages\sqlalchemy\orm\query.py", line 2903, in _iter
    result = self.session.execute(
  File "C:\Users\1\Desktop\Udacity\Fyyur Project\env\lib\site-packages\sqlalchemy\orm\session.py", line 1695, in execute
    conn = self._connection_for_bind(bind)
  File "C:\Users\1\Desktop\Udacity\Fyyur Project\env\lib\site-packages\sqlalchemy\orm\session.py", line 1536, in _connection_for_bind
    return self._transaction._connection_for_bind(
  File "C:\Users\1\Desktop\Udacity\Fyyur Project\env\lib\site-packages\sqlalchemy\orm\session.py", line 747, in _connection_for_bind
    conn = bind.connect()
  File "C:\Users\1\Desktop\Udacity\Fyyur Project\env\lib\site-packages\sqlalchemy\engine\base.py", line 3234, in connect
    return self._connection_cls(self, close_with_result=close_with_result)
  File "C:\Users\1\Desktop\Udacity\Fyyur Project\env\lib\site-packages\sqlalchemy\engine\base.py", line 96, in __init__
    else engine.raw_connection()
  File "C:\Users\1\Desktop\Udacity\Fyyur Project\env\lib\site-packages\sqlalchemy\engine\base.py", line 3313, in raw_connection
    return self._wrap_pool_connect(self.pool.connect, _connection)
  File "C:\Users\1\Desktop\Udacity\Fyyur Project\env\lib\site-packages\sqlalchemy\engine\base.py", line 3283, in _wrap_pool_connect
    Connection._handle_dbapi_exception_noconnection(
  File "C:\Users\1\Desktop\Udacity\Fyyur Project\env\lib\site-packages\sqlalchemy\engine\base.py", line 2117, in _handle_dbapi_exception_noconnection
    util.raise_(
  File "C:\Users\1\Desktop\Udacity\Fyyur Project\env\lib\site-packages\sqlalchemy\util\compat.py", line 207, in raise_
    raise exception
  File "C:\Users\1\Desktop\Udacity\Fyyur Project\env\lib\site-packages\sqlalchemy\engine\base.py", line 3280, in _wrap_pool_connect
    return fn()
  File "C:\Users\1\Desktop\Udacity\Fyyur Project\env\lib\site-packages\sqlalchemy\pool\base.py", line 310, in connect
    return _ConnectionFairy._checkout(self)
  File "C:\Users\1\Desktop\Udacity\Fyyur Project\env\lib\site-packages\sqlalchemy\pool\base.py", line 868, in _checkout
    fairy = _ConnectionRecord.checkout(pool)
  File "C:\Users\1\Desktop\Udacity\Fyyur Project\env\lib\site-packages\sqlalchemy\pool\base.py", line 476, in checkout
    rec = pool._do_get()
  File "C:\Users\1\Desktop\Udacity\Fyyur Project\env\lib\site-packages\sqlalchemy\pool\impl.py", line 145, in _do_get
    with util.safe_reraise():
  File "C:\Users\1\Desktop\Udacity\Fyyur Project\env\lib\site-packages\sqlalchemy\util\langhelpers.py", line 70, in __exit__
    compat.raise_(
  File "C:\Users\1\Desktop\Udacity\Fyyur Project\env\lib\site-packages\sqlalchemy\util\compat.py", line 207, in raise_
    raise exception
  File "C:\Users\1\Desktop\Udacity\Fyyur Project\env\lib\site-packages\sqlalchemy\pool\impl.py", line 143, in _do_get
    return self._create_connection()
  File "C:\Users\1\Desktop\Udacity\Fyyur Project\env\lib\site-packages\sqlalchemy\pool\base.py", line 256, in _create_connection
    return _ConnectionRecord(self)
  File "C:\Users\1\Desktop\Udacity\Fyyur Project\env\lib\site-packages\sqlalchemy\pool\base.py", line 371, in __init__
    self.__connect()
  File "C:\Users\1\Desktop\Udacity\Fyyur Project\env\lib\site-packages\sqlalchemy\pool\base.py", line 665, in __connect
    with util.safe_reraise():
  File "C:\Users\1\Desktop\Udacity\Fyyur Project\env\lib\site-packages\sqlalchemy\util\langhelpers.py", line 70, in __exit__
    compat.raise_(
  File "C:\Users\1\Desktop\Udacity\Fyyur Project\env\lib\site-packages\sqlalchemy\util\compat.py", line 207, in raise_
    raise exception
  File "C:\Users\1\Desktop\Udacity\Fyyur Project\env\lib\site-packages\sqlalchemy\pool\base.py", line 661, in __connect
    self.dbapi_connection = connection = pool._invoke_creator(self)
  File "C:\Users\1\Desktop\Udacity\Fyyur Project\env\lib\site-packages\sqlalchemy\engine\create.py", line 590, in connect
    return dialect.connect(*cargs, **cparams)
  File "C:\Users\1\Desktop\Udacity\Fyyur Project\env\lib\site-packages\sqlalchemy\engine\default.py", line 597, in connect
    return self.dbapi.connect(*cargs, **cparams)
  File "C:\Users\1\Desktop\Udacity\Fyyur Project\env\lib\site-packages\psycopg2\__init__.py", line 122, in connect
    conn = _connect(dsn, connection_factory=connection_factory, **kwasync)
sqlalchemy.exc.OperationalError: (psycopg2.OperationalError) connection to server at "localhost" (::1), port 5432 failed: FATAL:  database "Fyyur" does not exist

(Background on this error at: https://sqlalche.me/e/14/e3q8)
2022-06-01 12:20:00,869 INFO: errors [in C:\Users\1\Desktop\Udacity\Fyyur Project\app.py:729]
2022-06-01 12:20:03,449 ERROR: Exception on /shows [GET] [in C:\Users\1\Desktop\Udacity\Fyyur Project\env\lib\site-packages\flask\app.py:1455]
Traceback (most recent call last):
  File "C:\Users\1\Desktop\Udacity\Fyyur Project\env\lib\site-packages\sqlalchemy\engine\base.py", line 3280, in _wrap_pool_connect
    return fn()
  File "C:\Users\1\Desktop\Udacity\Fyyur Project\env\lib\site-packages\sqlalchemy\pool\base.py", line 310, in connect
    return _ConnectionFairy._checkout(self)
  File "C:\Users\1\Desktop\Udacity\Fyyur Project\env\lib\site-packages\sqlalchemy\pool\base.py", line 868, in _checkout
    fairy = _ConnectionRecord.checkout(pool)
  File "C:\Users\1\Desktop\Udacity\Fyyur Project\env\lib\site-packages\sqlalchemy\pool\base.py", line 476, in checkout
    rec = pool._do_get()
  File "C:\Users\1\Desktop\Udacity\Fyyur Project\env\lib\site-packages\sqlalchemy\pool\impl.py", line 145, in _do_get
    with util.safe_reraise():
  File "C:\Users\1\Desktop\Udacity\Fyyur Project\env\lib\site-packages\sqlalchemy\util\langhelpers.py", line 70, in __exit__
    compat.raise_(
  File "C:\Users\1\Desktop\Udacity\Fyyur Project\env\lib\site-packages\sqlalchemy\util\compat.py", line 207, in raise_
    raise exception
  File "C:\Users\1\Desktop\Udacity\Fyyur Project\env\lib\site-packages\sqlalchemy\pool\impl.py", line 143, in _do_get
    return self._create_connection()
  File "C:\Users\1\Desktop\Udacity\Fyyur Project\env\lib\site-packages\sqlalchemy\pool\base.py", line 256, in _create_connection
    return _ConnectionRecord(self)
  File "C:\Users\1\Desktop\Udacity\Fyyur Project\env\lib\site-packages\sqlalchemy\pool\base.py", line 371, in __init__
    self.__connect()
  File "C:\Users\1\Desktop\Udacity\Fyyur Project\env\lib\site-packages\sqlalchemy\pool\base.py", line 665, in __connect
    with util.safe_reraise():
  File "C:\Users\1\Desktop\Udacity\Fyyur Project\env\lib\site-packages\sqlalchemy\util\langhelpers.py", line 70, in __exit__
    compat.raise_(
  File "C:\Users\1\Desktop\Udacity\Fyyur Project\env\lib\site-packages\sqlalchemy\util\compat.py", line 207, in raise_
    raise exception
  File "C:\Users\1\Desktop\Udacity\Fyyur Project\env\lib\site-packages\sqlalchemy\pool\base.py", line 661, in __connect
    self.dbapi_connection = connection = pool._invoke_creator(self)
  File "C:\Users\1\Desktop\Udacity\Fyyur Project\env\lib\site-packages\sqlalchemy\engine\create.py", line 590, in connect
    return dialect.connect(*cargs, **cparams)
  File "C:\Users\1\Desktop\Udacity\Fyyur Project\env\lib\site-packages\sqlalchemy\engine\default.py", line 597, in connect
    return self.dbapi.connect(*cargs, **cparams)
  File "C:\Users\1\Desktop\Udacity\Fyyur Project\env\lib\site-packages\psycopg2\__init__.py", line 122, in connect
    conn = _connect(dsn, connection_factory=connection_factory, **kwasync)
psycopg2.OperationalError: connection to server at "localhost" (::1), port 5432 failed: FATAL:  database "Fyyur" does not exist


The above exception was the direct cause of the following exception:

Traceback (most recent call last):
  File "C:\Users\1\Desktop\Udacity\Fyyur Project\env\lib\site-packages\flask\app.py", line 2077, in wsgi_app
    response = self.full_dispatch_request()
  File "C:\Users\1\Desktop\Udacity\Fyyur Project\env\lib\site-packages\flask\app.py", line 1525, in full_dispatch_request
    rv = self.handle_user_exception(e)
  File "C:\Users\1\Desktop\Udacity\Fyyur Project\env\lib\site-packages\flask\app.py", line 1523, in full_dispatch_request
    rv = self.dispatch_request()
  File "C:\Users\1\Desktop\Udacity\Fyyur Project\env\lib\site-packages\flask\app.py", line 1509, in dispatch_request
    return self.ensure_sync(self.view_functions[rule.endpoint])(**req.view_args)
  File "C:\Users\1\Desktop\Udacity\Fyyur Project\app.py", line 665, in shows
    for show in db.session.query(Show).join(Artist).join(Venue).all():
  File "C:\Users\1\Desktop\Udacity\Fyyur Project\env\lib\site-packages\sqlalchemy\orm\query.py", line 2768, in all
    return self._iter().all()
  File "C:\Users\1\Desktop\Udacity\Fyyur Project\env\lib\site-packages\sqlalchemy\orm\query.py", line 2903, in _iter
    result = self.session.execute(
  File "C:\Users\1\Desktop\Udacity\Fyyur Project\env\lib\site-packages\sqlalchemy\orm\session.py", line 1695, in execute
    conn = self._connection_for_bind(bind)
  File "C:\Users\1\Desktop\Udacity\Fyyur Project\env\lib\site-packages\sqlalchemy\orm\session.py", line 1536, in _connection_for_bind
    return self._transaction._connection_for_bind(
  File "C:\Users\1\Desktop\Udacity\Fyyur Project\env\lib\site-packages\sqlalchemy\orm\session.py", line 747, in _connection_for_bind
    conn = bind.connect()
  File "C:\Users\1\Desktop\Udacity\Fyyur Project\env\lib\site-packages\sqlalchemy\engine\base.py", line 3234, in connect
    return self._connection_cls(self, close_with_result=close_with_result)
  File "C:\Users\1\Desktop\Udacity\Fyyur Project\env\lib\site-packages\sqlalchemy\engine\base.py", line 96, in __init__
    else engine.raw_connection()
  File "C:\Users\1\Desktop\Udacity\Fyyur Project\env\lib\site-packages\sqlalchemy\engine\base.py", line 3313, in raw_connection
    return self._wrap_pool_connect(self.pool.connect, _connection)
  File "C:\Users\1\Desktop\Udacity\Fyyur Project\env\lib\site-packages\sqlalchemy\engine\base.py", line 3283, in _wrap_pool_connect
    Connection._handle_dbapi_exception_noconnection(
  File "C:\Users\1\Desktop\Udacity\Fyyur Project\env\lib\site-packages\sqlalchemy\engine\base.py", line 2117, in _handle_dbapi_exception_noconnection
    util.raise_(
  File "C:\Users\1\Desktop\Udacity\Fyyur Project\env\lib\site-packages\sqlalchemy\util\compat.py", line 207, in raise_
    raise exception
  File "C:\Users\1\Desktop\Udacity\Fyyur Project\env\lib\site-packages\sqlalchemy\engine\base.py", line 3280, in _wrap_pool_connect
    return fn()
  File "C:\Users\1\Desktop\Udacity\Fyyur Project\env\lib\site-packages\sqlalchemy\pool\base.py", line 310, in connect
    return _ConnectionFairy._checkout(self)
  File "C:\Users\1\Desktop\Udacity\Fyyur Project\env\lib\site-packages\sqlalchemy\pool\base.py", line 868, in _checkout
    fairy = _ConnectionRecord.checkout(pool)
  File "C:\Users\1\Desktop\Udacity\Fyyur Project\env\lib\site-packages\sqlalchemy\pool\base.py", line 476, in checkout
    rec = pool._do_get()
  File "C:\Users\1\Desktop\Udacity\Fyyur Project\env\lib\site-packages\sqlalchemy\pool\impl.py", line 145, in _do_get
    with util.safe_reraise():
  File "C:\Users\1\Desktop\Udacity\Fyyur Project\env\lib\site-packages\sqlalchemy\util\langhelpers.py", line 70, in __exit__
    compat.raise_(
  File "C:\Users\1\Desktop\Udacity\Fyyur Project\env\lib\site-packages\sqlalchemy\util\compat.py", line 207, in raise_
    raise exception
  File "C:\Users\1\Desktop\Udacity\Fyyur Project\env\lib\site-packages\sqlalchemy\pool\impl.py", line 143, in _do_get
    return self._create_connection()
  File "C:\Users\1\Desktop\Udacity\Fyyur Project\env\lib\site-packages\sqlalchemy\pool\base.py", line 256, in _create_connection
    return _ConnectionRecord(self)
  File "C:\Users\1\Desktop\Udacity\Fyyur Project\env\lib\site-packages\sqlalchemy\pool\base.py", line 371, in __init__
    self.__connect()
  File "C:\Users\1\Desktop\Udacity\Fyyur Project\env\lib\site-packages\sqlalchemy\pool\base.py", line 665, in __connect
    with util.safe_reraise():
  File "C:\Users\1\Desktop\Udacity\Fyyur Project\env\lib\site-packages\sqlalchemy\util\langhelpers.py", line 70, in __exit__
    compat.raise_(
  File "C:\Users\1\Desktop\Udacity\Fyyur Project\env\lib\site-packages\sqlalchemy\util\compat.py", line 207, in raise_
    raise exception
  File "C:\Users\1\Desktop\Udacity\Fyyur Project\env\lib\site-packages\sqlalchemy\pool\base.py", line 661, in __connect
    self.dbapi_connection = connection = pool._invoke_creator(self)
  File "C:\Users\1\Desktop\Udacity\Fyyur Project\env\lib\site-packages\sqlalchemy\engine\create.py", line 590, in connect
    return dialect.connect(*cargs, **cparams)
  File "C:\Users\1\Desktop\Udacity\Fyyur Project\env\lib\site-packages\sqlalchemy\engine\default.py", line 597, in connect
    return self.dbapi.connect(*cargs, **cparams)
  File "C:\Users\1\Desktop\Udacity\Fyyur Project\env\lib\site-packages\psycopg2\__init__.py", line 122, in connect
    conn = _connect(dsn, connection_factory=connection_factory, **kwasync)
sqlalchemy.exc.OperationalError: (psycopg2.OperationalError) connection to server at "localhost" (::1), port 5432 failed: FATAL:  database "Fyyur" does not exist

(Background on this error at: https://sqlalche.me/e/14/e3q8)
2022-06-01 12:20:18,262 ERROR: Exception on /venues [GET] [in C:\Users\1\Desktop\Udacity\Fyyur Project\env\lib\site-packages\flask\app.py:1455]
Traceback (most recent call last):
  File "C:\Users\1\Desktop\Udacity\Fyyur Project\env\lib\site-packages\sqlalchemy\engine\base.py", line 3280, in _wrap_pool_connect
    return fn()
  File "C:\Users\1\Desktop\Udacity\Fyyur Project\env\lib\site-packages\sqlalchemy\pool\base.py", line 310, in connect
    return _ConnectionFairy._checkout(self)
  File "C:\Users\1\Desktop\Udacity\Fyyur Project\env\lib\site-packages\sqlalchemy\pool\base.py", line 868, in _checkout
    fairy = _ConnectionRecord.checkout(pool)
  File "C:\Users\1\Desktop\Udacity\Fyyur Project\env\lib\site-packages\sqlalchemy\pool\base.py", line 476, in checkout
    rec = pool._do_get()
  File "C:\Users\1\Desktop\Udacity\Fyyur Project\env\lib\site-packages\sqlalchemy\pool\impl.py", line 145, in _do_get
    with util.safe_reraise():
  File "C:\Users\1\Desktop\Udacity\Fyyur Project\env\lib\site-packages\sqlalchemy\util\langhelpers.py", line 70, in __exit__
    compat.raise_(
  File "C:\Users\1\Desktop\Udacity\Fyyur Project\env\lib\site-packages\sqlalchemy\util\compat.py", line 207, in raise_
    raise exception
  File "C:\Users\1\Desktop\Udacity\Fyyur Project\env\lib\site-packages\sqlalchemy\pool\impl.py", line 143, in _do_get
    return self._create_connection()
  File "C:\Users\1\Desktop\Udacity\Fyyur Project\env\lib\site-packages\sqlalchemy\pool\base.py", line 256, in _create_connection
    return _ConnectionRecord(self)
  File "C:\Users\1\Desktop\Udacity\Fyyur Project\env\lib\site-packages\sqlalchemy\pool\base.py", line 371, in __init__
    self.__connect()
  File "C:\Users\1\Desktop\Udacity\Fyyur Project\env\lib\site-packages\sqlalchemy\pool\base.py", line 665, in __connect
    with util.safe_reraise():
  File "C:\Users\1\Desktop\Udacity\Fyyur Project\env\lib\site-packages\sqlalchemy\util\langhelpers.py", line 70, in __exit__
    compat.raise_(
  File "C:\Users\1\Desktop\Udacity\Fyyur Project\env\lib\site-packages\sqlalchemy\util\compat.py", line 207, in raise_
    raise exception
  File "C:\Users\1\Desktop\Udacity\Fyyur Project\env\lib\site-packages\sqlalchemy\pool\base.py", line 661, in __connect
    self.dbapi_connection = connection = pool._invoke_creator(self)
  File "C:\Users\1\Desktop\Udacity\Fyyur Project\env\lib\site-packages\sqlalchemy\engine\create.py", line 590, in connect
    return dialect.connect(*cargs, **cparams)
  File "C:\Users\1\Desktop\Udacity\Fyyur Project\env\lib\site-packages\sqlalchemy\engine\default.py", line 597, in connect
    return self.dbapi.connect(*cargs, **cparams)
  File "C:\Users\1\Desktop\Udacity\Fyyur Project\env\lib\site-packages\psycopg2\__init__.py", line 122, in connect
    conn = _connect(dsn, connection_factory=connection_factory, **kwasync)
psycopg2.OperationalError: connection to server at "localhost" (::1), port 5432 failed: FATAL:  database "Fyyur" does not exist


The above exception was the direct cause of the following exception:

Traceback (most recent call last):
  File "C:\Users\1\Desktop\Udacity\Fyyur Project\env\lib\site-packages\flask\app.py", line 2077, in wsgi_app
    response = self.full_dispatch_request()
  File "C:\Users\1\Desktop\Udacity\Fyyur Project\env\lib\site-packages\flask\app.py", line 1525, in full_dispatch_request
    rv = self.handle_user_exception(e)
  File "C:\Users\1\Desktop\Udacity\Fyyur Project\env\lib\site-packages\flask\app.py", line 1523, in full_dispatch_request
    rv = self.dispatch_request()
  File "C:\Users\1\Desktop\Udacity\Fyyur Project\env\lib\site-packages\flask\app.py", line 1509, in dispatch_request
    return self.ensure_sync(self.view_functions[rule.endpoint])(**req.view_args)
  File "C:\Users\1\Desktop\Udacity\Fyyur Project\app.py", line 180, in venues
    .all()
  File "C:\Users\1\Desktop\Udacity\Fyyur Project\env\lib\site-packages\sqlalchemy\orm\query.py", line 2768, in all
    return self._iter().all()
  File "C:\Users\1\Desktop\Udacity\Fyyur Project\env\lib\site-packages\sqlalchemy\orm\query.py", line 2903, in _iter
    result = self.session.execute(
  File "C:\Users\1\Desktop\Udacity\Fyyur Project\env\lib\site-packages\sqlalchemy\orm\session.py", line 1695, in execute
    conn = self._connection_for_bind(bind)
  File "C:\Users\1\Desktop\Udacity\Fyyur Project\env\lib\site-packages\sqlalchemy\orm\session.py", line 1536, in _connection_for_bind
    return self._transaction._connection_for_bind(
  File "C:\Users\1\Desktop\Udacity\Fyyur Project\env\lib\site-packages\sqlalchemy\orm\session.py", line 747, in _connection_for_bind
    conn = bind.connect()
  File "C:\Users\1\Desktop\Udacity\Fyyur Project\env\lib\site-packages\sqlalchemy\engine\base.py", line 3234, in connect
    return self._connection_cls(self, close_with_result=close_with_result)
  File "C:\Users\1\Desktop\Udacity\Fyyur Project\env\lib\site-packages\sqlalchemy\engine\base.py", line 96, in __init__
    else engine.raw_connection()
  File "C:\Users\1\Desktop\Udacity\Fyyur Project\env\lib\site-packages\sqlalchemy\engine\base.py", line 3313, in raw_connection
    return self._wrap_pool_connect(self.pool.connect, _connection)
  File "C:\Users\1\Desktop\Udacity\Fyyur Project\env\lib\site-packages\sqlalchemy\engine\base.py", line 3283, in _wrap_pool_connect
    Connection._handle_dbapi_exception_noconnection(
  File "C:\Users\1\Desktop\Udacity\Fyyur Project\env\lib\site-packages\sqlalchemy\engine\base.py", line 2117, in _handle_dbapi_exception_noconnection
    util.raise_(
  File "C:\Users\1\Desktop\Udacity\Fyyur Project\env\lib\site-packages\sqlalchemy\util\compat.py", line 207, in raise_
    raise exception
  File "C:\Users\1\Desktop\Udacity\Fyyur Project\env\lib\site-packages\sqlalchemy\engine\base.py", line 3280, in _wrap_pool_connect
    return fn()
  File "C:\Users\1\Desktop\Udacity\Fyyur Project\env\lib\site-packages\sqlalchemy\pool\base.py", line 310, in connect
    return _ConnectionFairy._checkout(self)
  File "C:\Users\1\Desktop\Udacity\Fyyur Project\env\lib\site-packages\sqlalchemy\pool\base.py", line 868, in _checkout
    fairy = _ConnectionRecord.checkout(pool)
  File "C:\Users\1\Desktop\Udacity\Fyyur Project\env\lib\site-packages\sqlalchemy\pool\base.py", line 476, in checkout
    rec = pool._do_get()
  File "C:\Users\1\Desktop\Udacity\Fyyur Project\env\lib\site-packages\sqlalchemy\pool\impl.py", line 145, in _do_get
    with util.safe_reraise():
  File "C:\Users\1\Desktop\Udacity\Fyyur Project\env\lib\site-packages\sqlalchemy\util\langhelpers.py", line 70, in __exit__
    compat.raise_(
  File "C:\Users\1\Desktop\Udacity\Fyyur Project\env\lib\site-packages\sqlalchemy\util\compat.py", line 207, in raise_
    raise exception
  File "C:\Users\1\Desktop\Udacity\Fyyur Project\env\lib\site-packages\sqlalchemy\pool\impl.py", line 143, in _do_get
    return self._create_connection()
  File "C:\Users\1\Desktop\Udacity\Fyyur Project\env\lib\site-packages\sqlalchemy\pool\base.py", line 256, in _create_connection
    return _ConnectionRecord(self)
  File "C:\Users\1\Desktop\Udacity\Fyyur Project\env\lib\site-packages\sqlalchemy\pool\base.py", line 371, in __init__
    self.__connect()
  File "C:\Users\1\Desktop\Udacity\Fyyur Project\env\lib\site-packages\sqlalchemy\pool\base.py", line 665, in __connect
    with util.safe_reraise():
  File "C:\Users\1\Desktop\Udacity\Fyyur Project\env\lib\site-packages\sqlalchemy\util\langhelpers.py", line 70, in __exit__
    compat.raise_(
  File "C:\Users\1\Desktop\Udacity\Fyyur Project\env\lib\site-packages\sqlalchemy\util\compat.py", line 207, in raise_
    raise exception
  File "C:\Users\1\Desktop\Udacity\Fyyur Project\env\lib\site-packages\sqlalchemy\pool\base.py", line 661, in __connect
    self.dbapi_connection = connection = pool._invoke_creator(self)
  File "C:\Users\1\Desktop\Udacity\Fyyur Project\env\lib\site-packages\sqlalchemy\engine\create.py", line 590, in connect
    return dialect.connect(*cargs, **cparams)
  File "C:\Users\1\Desktop\Udacity\Fyyur Project\env\lib\site-packages\sqlalchemy\engine\default.py", line 597, in connect
    return self.dbapi.connect(*cargs, **cparams)
  File "C:\Users\1\Desktop\Udacity\Fyyur Project\env\lib\site-packages\psycopg2\__init__.py", line 122, in connect
    conn = _connect(dsn, connection_factory=connection_factory, **kwasync)
sqlalchemy.exc.OperationalError: (psycopg2.OperationalError) connection to server at "localhost" (::1), port 5432 failed: FATAL:  database "Fyyur" does not exist

(Background on this error at: https://sqlalche.me/e/14/e3q8)
2022-06-01 12:20:22,222 ERROR: Exception on /shows/create [GET] [in C:\Users\1\Desktop\Udacity\Fyyur Project\env\lib\site-packages\flask\app.py:1455]
Traceback (most recent call last):
  File "C:\Users\1\Desktop\Udacity\Fyyur Project\env\lib\site-packages\flask\app.py", line 2077, in wsgi_app
    response = self.full_dispatch_request()
  File "C:\Users\1\Desktop\Udacity\Fyyur Project\env\lib\site-packages\flask\app.py", line 1525, in full_dispatch_request
    rv = self.handle_user_exception(e)
  File "C:\Users\1\Desktop\Udacity\Fyyur Project\env\lib\site-packages\flask\app.py", line 1523, in full_dispatch_request
    rv = self.dispatch_request()
  File "C:\Users\1\Desktop\Udacity\Fyyur Project\env\lib\site-packages\flask\app.py", line 1509, in dispatch_request
    return self.ensure_sync(self.view_functions[rule.endpoint])(**req.view_args)
  File "C:\Users\1\Desktop\Udacity\Fyyur Project\app.py", line 682, in create_shows
    form = ShowForm()
  File "C:\Users\1\Desktop\Udacity\Fyyur Project\env\lib\site-packages\wtforms\form.py", line 208, in __call__
    return type.__call__(cls, *args, **kwargs)
  File "C:\Users\1\Desktop\Udacity\Fyyur Project\env\lib\site-packages\flask_wtf\form.py", line 87, in __init__
    super(FlaskForm, self).__init__(formdata=formdata, **kwargs)
  File "C:\Users\1\Desktop\Udacity\Fyyur Project\env\lib\site-packages\wtforms\form.py", line 286, in __init__
    self.process(formdata, obj, data=data, **kwargs)
  File "C:\Users\1\Desktop\Udacity\Fyyur Project\env\lib\site-packages\wtforms\form.py", line 127, in process
    field.process(formdata, data, extra_filters=field_extra_filters)
  File "C:\Users\1\Desktop\Udacity\Fyyur Project\env\lib\site-packages\wtforms\csrf\core.py", line 44, in process
    self.current_token = self.csrf_impl.generate_csrf_token(self)
  File "C:\Users\1\Desktop\Udacity\Fyyur Project\env\lib\site-packages\flask_wtf\csrf.py", line 139, in generate_csrf_token
    return generate_csrf(
  File "C:\Users\1\Desktop\Udacity\Fyyur Project\env\lib\site-packages\flask_wtf\csrf.py", line 33, in generate_csrf
    secret_key = _get_config(
  File "C:\Users\1\Desktop\Udacity\Fyyur Project\env\lib\site-packages\flask_wtf\csrf.py", line 128, in _get_config
    raise RuntimeError(message)
RuntimeError: A secret key is required to use CSRF.
2022-06-01 12:23:18,791 INFO: errors [in C:\Users\1\Desktop\Udacity\Fyyur Project\app.py:729]
2022-06-01 12:24:22,131 INFO: errors [in C:\Users\1\Desktop\Udacity\Fyyur Project\app.py:729]
2022-06-01 12:24:46,222 ERROR: Exception on /venues [GET] [in C:\Users\1\Desktop\Udacity\Fyyur Project\env\lib\site-packages\flask\app.py:1455]
Traceback (most recent call last):
  File "C:\Users\1\Desktop\Udacity\Fyyur Project\env\lib\site-packages\sqlalchemy\engine\base.py", line 3280, in _wrap_pool_connect
    return fn()
  File "C:\Users\1\Desktop\Udacity\Fyyur Project\env\lib\site-packages\sqlalchemy\pool\base.py", line 310, in connect
    return _ConnectionFairy._checkout(self)
  File "C:\Users\1\Desktop\Udacity\Fyyur Project\env\lib\site-packages\sqlalchemy\pool\base.py", line 868, in _checkout
    fairy = _ConnectionRecord.checkout(pool)
  File "C:\Users\1\Desktop\Udacity\Fyyur Project\env\lib\site-packages\sqlalchemy\pool\base.py", line 476, in checkout
    rec = pool._do_get()
  File "C:\Users\1\Desktop\Udacity\Fyyur Project\env\lib\site-packages\sqlalchemy\pool\impl.py", line 145, in _do_get
    with util.safe_reraise():
  File "C:\Users\1\Desktop\Udacity\Fyyur Project\env\lib\site-packages\sqlalchemy\util\langhelpers.py", line 70, in __exit__
    compat.raise_(
  File "C:\Users\1\Desktop\Udacity\Fyyur Project\env\lib\site-packages\sqlalchemy\util\compat.py", line 207, in raise_
    raise exception
  File "C:\Users\1\Desktop\Udacity\Fyyur Project\env\lib\site-packages\sqlalchemy\pool\impl.py", line 143, in _do_get
    return self._create_connection()
  File "C:\Users\1\Desktop\Udacity\Fyyur Project\env\lib\site-packages\sqlalchemy\pool\base.py", line 256, in _create_connection
    return _ConnectionRecord(self)
  File "C:\Users\1\Desktop\Udacity\Fyyur Project\env\lib\site-packages\sqlalchemy\pool\base.py", line 371, in __init__
    self.__connect()
  File "C:\Users\1\Desktop\Udacity\Fyyur Project\env\lib\site-packages\sqlalchemy\pool\base.py", line 665, in __connect
    with util.safe_reraise():
  File "C:\Users\1\Desktop\Udacity\Fyyur Project\env\lib\site-packages\sqlalchemy\util\langhelpers.py", line 70, in __exit__
    compat.raise_(
  File "C:\Users\1\Desktop\Udacity\Fyyur Project\env\lib\site-packages\sqlalchemy\util\compat.py", line 207, in raise_
    raise exception
  File "C:\Users\1\Desktop\Udacity\Fyyur Project\env\lib\site-packages\sqlalchemy\pool\base.py", line 661, in __connect
    self.dbapi_connection = connection = pool._invoke_creator(self)
  File "C:\Users\1\Desktop\Udacity\Fyyur Project\env\lib\site-packages\sqlalchemy\engine\create.py", line 590, in connect
    return dialect.connect(*cargs, **cparams)
  File "C:\Users\1\Desktop\Udacity\Fyyur Project\env\lib\site-packages\sqlalchemy\engine\default.py", line 597, in connect
    return self.dbapi.connect(*cargs, **cparams)
  File "C:\Users\1\Desktop\Udacity\Fyyur Project\env\lib\site-packages\psycopg2\__init__.py", line 122, in connect
    conn = _connect(dsn, connection_factory=connection_factory, **kwasync)
psycopg2.OperationalError: connection to server at "localhost" (::1), port 5432 failed: FATAL:  database "Fyyur" does not exist


The above exception was the direct cause of the following exception:

Traceback (most recent call last):
  File "C:\Users\1\Desktop\Udacity\Fyyur Project\env\lib\site-packages\flask\app.py", line 2077, in wsgi_app
    response = self.full_dispatch_request()
  File "C:\Users\1\Desktop\Udacity\Fyyur Project\env\lib\site-packages\flask\app.py", line 1525, in full_dispatch_request
    rv = self.handle_user_exception(e)
  File "C:\Users\1\Desktop\Udacity\Fyyur Project\env\lib\site-packages\flask\app.py", line 1523, in full_dispatch_request
    rv = self.dispatch_request()
  File "C:\Users\1\Desktop\Udacity\Fyyur Project\env\lib\site-packages\flask\app.py", line 1509, in dispatch_request
    return self.ensure_sync(self.view_functions[rule.endpoint])(**req.view_args)
  File "C:\Users\1\Desktop\Udacity\Fyyur Project\app.py", line 180, in venues
    .all()
  File "C:\Users\1\Desktop\Udacity\Fyyur Project\env\lib\site-packages\sqlalchemy\orm\query.py", line 2768, in all
    return self._iter().all()
  File "C:\Users\1\Desktop\Udacity\Fyyur Project\env\lib\site-packages\sqlalchemy\orm\query.py", line 2903, in _iter
    result = self.session.execute(
  File "C:\Users\1\Desktop\Udacity\Fyyur Project\env\lib\site-packages\sqlalchemy\orm\session.py", line 1695, in execute
    conn = self._connection_for_bind(bind)
  File "C:\Users\1\Desktop\Udacity\Fyyur Project\env\lib\site-packages\sqlalchemy\orm\session.py", line 1536, in _connection_for_bind
    return self._transaction._connection_for_bind(
  File "C:\Users\1\Desktop\Udacity\Fyyur Project\env\lib\site-packages\sqlalchemy\orm\session.py", line 747, in _connection_for_bind
    conn = bind.connect()
  File "C:\Users\1\Desktop\Udacity\Fyyur Project\env\lib\site-packages\sqlalchemy\engine\base.py", line 3234, in connect
    return self._connection_cls(self, close_with_result=close_with_result)
  File "C:\Users\1\Desktop\Udacity\Fyyur Project\env\lib\site-packages\sqlalchemy\engine\base.py", line 96, in __init__
    else engine.raw_connection()
  File "C:\Users\1\Desktop\Udacity\Fyyur Project\env\lib\site-packages\sqlalchemy\engine\base.py", line 3313, in raw_connection
    return self._wrap_pool_connect(self.pool.connect, _connection)
  File "C:\Users\1\Desktop\Udacity\Fyyur Project\env\lib\site-packages\sqlalchemy\engine\base.py", line 3283, in _wrap_pool_connect
    Connection._handle_dbapi_exception_noconnection(
  File "C:\Users\1\Desktop\Udacity\Fyyur Project\env\lib\site-packages\sqlalchemy\engine\base.py", line 2117, in _handle_dbapi_exception_noconnection
    util.raise_(
  File "C:\Users\1\Desktop\Udacity\Fyyur Project\env\lib\site-packages\sqlalchemy\util\compat.py", line 207, in raise_
    raise exception
  File "C:\Users\1\Desktop\Udacity\Fyyur Project\env\lib\site-packages\sqlalchemy\engine\base.py", line 3280, in _wrap_pool_connect
    return fn()
  File "C:\Users\1\Desktop\Udacity\Fyyur Project\env\lib\site-packages\sqlalchemy\pool\base.py", line 310, in connect
    return _ConnectionFairy._checkout(self)
  File "C:\Users\1\Desktop\Udacity\Fyyur Project\env\lib\site-packages\sqlalchemy\pool\base.py", line 868, in _checkout
    fairy = _ConnectionRecord.checkout(pool)
  File "C:\Users\1\Desktop\Udacity\Fyyur Project\env\lib\site-packages\sqlalchemy\pool\base.py", line 476, in checkout
    rec = pool._do_get()
  File "C:\Users\1\Desktop\Udacity\Fyyur Project\env\lib\site-packages\sqlalchemy\pool\impl.py", line 145, in _do_get
    with util.safe_reraise():
  File "C:\Users\1\Desktop\Udacity\Fyyur Project\env\lib\site-packages\sqlalchemy\util\langhelpers.py", line 70, in __exit__
    compat.raise_(
  File "C:\Users\1\Desktop\Udacity\Fyyur Project\env\lib\site-packages\sqlalchemy\util\compat.py", line 207, in raise_
    raise exception
  File "C:\Users\1\Desktop\Udacity\Fyyur Project\env\lib\site-packages\sqlalchemy\pool\impl.py", line 143, in _do_get
    return self._create_connection()
  File "C:\Users\1\Desktop\Udacity\Fyyur Project\env\lib\site-packages\sqlalchemy\pool\base.py", line 256, in _create_connection
    return _ConnectionRecord(self)
  File "C:\Users\1\Desktop\Udacity\Fyyur Project\env\lib\site-packages\sqlalchemy\pool\base.py", line 371, in __init__
    self.__connect()
  File "C:\Users\1\Desktop\Udacity\Fyyur Project\env\lib\site-packages\sqlalchemy\pool\base.py", line 665, in __connect
    with util.safe_reraise():
  File "C:\Users\1\Desktop\Udacity\Fyyur Project\env\lib\site-packages\sqlalchemy\util\langhelpers.py", line 70, in __exit__
    compat.raise_(
  File "C:\Users\1\Desktop\Udacity\Fyyur Project\env\lib\site-packages\sqlalchemy\util\compat.py", line 207, in raise_
    raise exception
  File "C:\Users\1\Desktop\Udacity\Fyyur Project\env\lib\site-packages\sqlalchemy\pool\base.py", line 661, in __connect
    self.dbapi_connection = connection = pool._invoke_creator(self)
  File "C:\Users\1\Desktop\Udacity\Fyyur Project\env\lib\site-packages\sqlalchemy\engine\create.py", line 590, in connect
    return dialect.connect(*cargs, **cparams)
  File "C:\Users\1\Desktop\Udacity\Fyyur Project\env\lib\site-packages\sqlalchemy\engine\default.py", line 597, in connect
    return self.dbapi.connect(*cargs, **cparams)
  File "C:\Users\1\Desktop\Udacity\Fyyur Project\env\lib\site-packages\psycopg2\__init__.py", line 122, in connect
    conn = _connect(dsn, connection_factory=connection_factory, **kwasync)
sqlalchemy.exc.OperationalError: (psycopg2.OperationalError) connection to server at "localhost" (::1), port 5432 failed: FATAL:  database "Fyyur" does not exist

(Background on this error at: https://sqlalche.me/e/14/e3q8)
2022-06-01 12:26:57,270 ERROR: Exception on /artists [GET] [in C:\Users\1\Desktop\Udacity\Fyyur Project\env\lib\site-packages\flask\app.py:1455]
Traceback (most recent call last):
  File "C:\Users\1\Desktop\Udacity\Fyyur Project\env\lib\site-packages\sqlalchemy\engine\base.py", line 3280, in _wrap_pool_connect
    return fn()
  File "C:\Users\1\Desktop\Udacity\Fyyur Project\env\lib\site-packages\sqlalchemy\pool\base.py", line 310, in connect
    return _ConnectionFairy._checkout(self)
  File "C:\Users\1\Desktop\Udacity\Fyyur Project\env\lib\site-packages\sqlalchemy\pool\base.py", line 868, in _checkout
    fairy = _ConnectionRecord.checkout(pool)
  File "C:\Users\1\Desktop\Udacity\Fyyur Project\env\lib\site-packages\sqlalchemy\pool\base.py", line 476, in checkout
    rec = pool._do_get()
  File "C:\Users\1\Desktop\Udacity\Fyyur Project\env\lib\site-packages\sqlalchemy\pool\impl.py", line 145, in _do_get
    with util.safe_reraise():
  File "C:\Users\1\Desktop\Udacity\Fyyur Project\env\lib\site-packages\sqlalchemy\util\langhelpers.py", line 70, in __exit__
    compat.raise_(
  File "C:\Users\1\Desktop\Udacity\Fyyur Project\env\lib\site-packages\sqlalchemy\util\compat.py", line 207, in raise_
    raise exception
  File "C:\Users\1\Desktop\Udacity\Fyyur Project\env\lib\site-packages\sqlalchemy\pool\impl.py", line 143, in _do_get
    return self._create_connection()
  File "C:\Users\1\Desktop\Udacity\Fyyur Project\env\lib\site-packages\sqlalchemy\pool\base.py", line 256, in _create_connection
    return _ConnectionRecord(self)
  File "C:\Users\1\Desktop\Udacity\Fyyur Project\env\lib\site-packages\sqlalchemy\pool\base.py", line 371, in __init__
    self.__connect()
  File "C:\Users\1\Desktop\Udacity\Fyyur Project\env\lib\site-packages\sqlalchemy\pool\base.py", line 665, in __connect
    with util.safe_reraise():
  File "C:\Users\1\Desktop\Udacity\Fyyur Project\env\lib\site-packages\sqlalchemy\util\langhelpers.py", line 70, in __exit__
    compat.raise_(
  File "C:\Users\1\Desktop\Udacity\Fyyur Project\env\lib\site-packages\sqlalchemy\util\compat.py", line 207, in raise_
    raise exception
  File "C:\Users\1\Desktop\Udacity\Fyyur Project\env\lib\site-packages\sqlalchemy\pool\base.py", line 661, in __connect
    self.dbapi_connection = connection = pool._invoke_creator(self)
  File "C:\Users\1\Desktop\Udacity\Fyyur Project\env\lib\site-packages\sqlalchemy\engine\create.py", line 590, in connect
    return dialect.connect(*cargs, **cparams)
  File "C:\Users\1\Desktop\Udacity\Fyyur Project\env\lib\site-packages\sqlalchemy\engine\default.py", line 597, in connect
    return self.dbapi.connect(*cargs, **cparams)
  File "C:\Users\1\Desktop\Udacity\Fyyur Project\env\lib\site-packages\psycopg2\__init__.py", line 122, in connect
    conn = _connect(dsn, connection_factory=connection_factory, **kwasync)
psycopg2.OperationalError: connection to server at "localhost" (::1), port 5432 failed: FATAL:  database "Fyyur" does not exist


The above exception was the direct cause of the following exception:

Traceback (most recent call last):
  File "C:\Users\1\Desktop\Udacity\Fyyur Project\env\lib\site-packages\flask\app.py", line 2077, in wsgi_app
    response = self.full_dispatch_request()
  File "C:\Users\1\Desktop\Udacity\Fyyur Project\env\lib\site-packages\flask\app.py", line 1525, in full_dispatch_request
    rv = self.handle_user_exception(e)
  File "C:\Users\1\Desktop\Udacity\Fyyur Project\env\lib\site-packages\flask\app.py", line 1523, in full_dispatch_request
    rv = self.dispatch_request()
  File "C:\Users\1\Desktop\Udacity\Fyyur Project\env\lib\site-packages\flask\app.py", line 1509, in dispatch_request
    return self.ensure_sync(self.view_functions[rule.endpoint])(**req.view_args)
  File "C:\Users\1\Desktop\Udacity\Fyyur Project\app.py", line 386, in artists
    artists = Artist.query.order_by("id").all()
  File "C:\Users\1\Desktop\Udacity\Fyyur Project\env\lib\site-packages\sqlalchemy\orm\query.py", line 2768, in all
    return self._iter().all()
  File "C:\Users\1\Desktop\Udacity\Fyyur Project\env\lib\site-packages\sqlalchemy\orm\query.py", line 2903, in _iter
    result = self.session.execute(
  File "C:\Users\1\Desktop\Udacity\Fyyur Project\env\lib\site-packages\sqlalchemy\orm\session.py", line 1695, in execute
    conn = self._connection_for_bind(bind)
  File "C:\Users\1\Desktop\Udacity\Fyyur Project\env\lib\site-packages\sqlalchemy\orm\session.py", line 1536, in _connection_for_bind
    return self._transaction._connection_for_bind(
  File "C:\Users\1\Desktop\Udacity\Fyyur Project\env\lib\site-packages\sqlalchemy\orm\session.py", line 747, in _connection_for_bind
    conn = bind.connect()
  File "C:\Users\1\Desktop\Udacity\Fyyur Project\env\lib\site-packages\sqlalchemy\engine\base.py", line 3234, in connect
    return self._connection_cls(self, close_with_result=close_with_result)
  File "C:\Users\1\Desktop\Udacity\Fyyur Project\env\lib\site-packages\sqlalchemy\engine\base.py", line 96, in __init__
    else engine.raw_connection()
  File "C:\Users\1\Desktop\Udacity\Fyyur Project\env\lib\site-packages\sqlalchemy\engine\base.py", line 3313, in raw_connection
    return self._wrap_pool_connect(self.pool.connect, _connection)
  File "C:\Users\1\Desktop\Udacity\Fyyur Project\env\lib\site-packages\sqlalchemy\engine\base.py", line 3283, in _wrap_pool_connect
    Connection._handle_dbapi_exception_noconnection(
  File "C:\Users\1\Desktop\Udacity\Fyyur Project\env\lib\site-packages\sqlalchemy\engine\base.py", line 2117, in _handle_dbapi_exception_noconnection
    util.raise_(
  File "C:\Users\1\Desktop\Udacity\Fyyur Project\env\lib\site-packages\sqlalchemy\util\compat.py", line 207, in raise_
    raise exception
  File "C:\Users\1\Desktop\Udacity\Fyyur Project\env\lib\site-packages\sqlalchemy\engine\base.py", line 3280, in _wrap_pool_connect
    return fn()
  File "C:\Users\1\Desktop\Udacity\Fyyur Project\env\lib\site-packages\sqlalchemy\pool\base.py", line 310, in connect
    return _ConnectionFairy._checkout(self)
  File "C:\Users\1\Desktop\Udacity\Fyyur Project\env\lib\site-packages\sqlalchemy\pool\base.py", line 868, in _checkout
    fairy = _ConnectionRecord.checkout(pool)
  File "C:\Users\1\Desktop\Udacity\Fyyur Project\env\lib\site-packages\sqlalchemy\pool\base.py", line 476, in checkout
    rec = pool._do_get()
  File "C:\Users\1\Desktop\Udacity\Fyyur Project\env\lib\site-packages\sqlalchemy\pool\impl.py", line 145, in _do_get
    with util.safe_reraise():
  File "C:\Users\1\Desktop\Udacity\Fyyur Project\env\lib\site-packages\sqlalchemy\util\langhelpers.py", line 70, in __exit__
    compat.raise_(
  File "C:\Users\1\Desktop\Udacity\Fyyur Project\env\lib\site-packages\sqlalchemy\util\compat.py", line 207, in raise_
    raise exception
  File "C:\Users\1\Desktop\Udacity\Fyyur Project\env\lib\site-packages\sqlalchemy\pool\impl.py", line 143, in _do_get
    return self._create_connection()
  File "C:\Users\1\Desktop\Udacity\Fyyur Project\env\lib\site-packages\sqlalchemy\pool\base.py", line 256, in _create_connection
    return _ConnectionRecord(self)
  File "C:\Users\1\Desktop\Udacity\Fyyur Project\env\lib\site-packages\sqlalchemy\pool\base.py", line 371, in __init__
    self.__connect()
  File "C:\Users\1\Desktop\Udacity\Fyyur Project\env\lib\site-packages\sqlalchemy\pool\base.py", line 665, in __connect
    with util.safe_reraise():
  File "C:\Users\1\Desktop\Udacity\Fyyur Project\env\lib\site-packages\sqlalchemy\util\langhelpers.py", line 70, in __exit__
    compat.raise_(
  File "C:\Users\1\Desktop\Udacity\Fyyur Project\env\lib\site-packages\sqlalchemy\util\compat.py", line 207, in raise_
    raise exception
  File "C:\Users\1\Desktop\Udacity\Fyyur Project\env\lib\site-packages\sqlalchemy\pool\base.py", line 661, in __connect
    self.dbapi_connection = connection = pool._invoke_creator(self)
  File "C:\Users\1\Desktop\Udacity\Fyyur Project\env\lib\site-packages\sqlalchemy\engine\create.py", line 590, in connect
    return dialect.connect(*cargs, **cparams)
  File "C:\Users\1\Desktop\Udacity\Fyyur Project\env\lib\site-packages\sqlalchemy\engine\default.py", line 597, in connect
    return self.dbapi.connect(*cargs, **cparams)
  File "C:\Users\1\Desktop\Udacity\Fyyur Project\env\lib\site-packages\psycopg2\__init__.py", line 122, in connect
    conn = _connect(dsn, connection_factory=connection_factory, **kwasync)
sqlalchemy.exc.OperationalError: (psycopg2.OperationalError) connection to server at "localhost" (::1), port 5432 failed: FATAL:  database "Fyyur" does not exist

(Background on this error at: https://sqlalche.me/e/14/e3q8)
2022-06-01 12:30:11,238 INFO: errors [in C:\Users\1\Desktop\Udacity\Fyyur Project\app.py:729]
2022-06-01 12:30:13,945 ERROR: Exception on /artists [GET] [in C:\Users\1\Desktop\Udacity\Fyyur Project\env\lib\site-packages\flask\app.py:1455]
Traceback (most recent call last):
  File "C:\Users\1\Desktop\Udacity\Fyyur Project\env\lib\site-packages\sqlalchemy\engine\base.py", line 3280, in _wrap_pool_connect
    return fn()
  File "C:\Users\1\Desktop\Udacity\Fyyur Project\env\lib\site-packages\sqlalchemy\pool\base.py", line 310, in connect
    return _ConnectionFairy._checkout(self)
  File "C:\Users\1\Desktop\Udacity\Fyyur Project\env\lib\site-packages\sqlalchemy\pool\base.py", line 868, in _checkout
    fairy = _ConnectionRecord.checkout(pool)
  File "C:\Users\1\Desktop\Udacity\Fyyur Project\env\lib\site-packages\sqlalchemy\pool\base.py", line 476, in checkout
    rec = pool._do_get()
  File "C:\Users\1\Desktop\Udacity\Fyyur Project\env\lib\site-packages\sqlalchemy\pool\impl.py", line 145, in _do_get
    with util.safe_reraise():
  File "C:\Users\1\Desktop\Udacity\Fyyur Project\env\lib\site-packages\sqlalchemy\util\langhelpers.py", line 70, in __exit__
    compat.raise_(
  File "C:\Users\1\Desktop\Udacity\Fyyur Project\env\lib\site-packages\sqlalchemy\util\compat.py", line 207, in raise_
    raise exception
  File "C:\Users\1\Desktop\Udacity\Fyyur Project\env\lib\site-packages\sqlalchemy\pool\impl.py", line 143, in _do_get
    return self._create_connection()
  File "C:\Users\1\Desktop\Udacity\Fyyur Project\env\lib\site-packages\sqlalchemy\pool\base.py", line 256, in _create_connection
    return _ConnectionRecord(self)
  File "C:\Users\1\Desktop\Udacity\Fyyur Project\env\lib\site-packages\sqlalchemy\pool\base.py", line 371, in __init__
    self.__connect()
  File "C:\Users\1\Desktop\Udacity\Fyyur Project\env\lib\site-packages\sqlalchemy\pool\base.py", line 665, in __connect
    with util.safe_reraise():
  File "C:\Users\1\Desktop\Udacity\Fyyur Project\env\lib\site-packages\sqlalchemy\util\langhelpers.py", line 70, in __exit__
    compat.raise_(
  File "C:\Users\1\Desktop\Udacity\Fyyur Project\env\lib\site-packages\sqlalchemy\util\compat.py", line 207, in raise_
    raise exception
  File "C:\Users\1\Desktop\Udacity\Fyyur Project\env\lib\site-packages\sqlalchemy\pool\base.py", line 661, in __connect
    self.dbapi_connection = connection = pool._invoke_creator(self)
  File "C:\Users\1\Desktop\Udacity\Fyyur Project\env\lib\site-packages\sqlalchemy\engine\create.py", line 590, in connect
    return dialect.connect(*cargs, **cparams)
  File "C:\Users\1\Desktop\Udacity\Fyyur Project\env\lib\site-packages\sqlalchemy\engine\default.py", line 597, in connect
    return self.dbapi.connect(*cargs, **cparams)
  File "C:\Users\1\Desktop\Udacity\Fyyur Project\env\lib\site-packages\psycopg2\__init__.py", line 122, in connect
    conn = _connect(dsn, connection_factory=connection_factory, **kwasync)
psycopg2.OperationalError: connection to server at "localhost" (::1), port 5432 failed: FATAL:  database "Fyyur" does not exist


The above exception was the direct cause of the following exception:

Traceback (most recent call last):
  File "C:\Users\1\Desktop\Udacity\Fyyur Project\env\lib\site-packages\flask\app.py", line 2077, in wsgi_app
    response = self.full_dispatch_request()
  File "C:\Users\1\Desktop\Udacity\Fyyur Project\env\lib\site-packages\flask\app.py", line 1525, in full_dispatch_request
    rv = self.handle_user_exception(e)
  File "C:\Users\1\Desktop\Udacity\Fyyur Project\env\lib\site-packages\flask\app.py", line 1523, in full_dispatch_request
    rv = self.dispatch_request()
  File "C:\Users\1\Desktop\Udacity\Fyyur Project\env\lib\site-packages\flask\app.py", line 1509, in dispatch_request
    return self.ensure_sync(self.view_functions[rule.endpoint])(**req.view_args)
  File "C:\Users\1\Desktop\Udacity\Fyyur Project\app.py", line 386, in artists
    artists = Artist.query.order_by("id").all()
  File "C:\Users\1\Desktop\Udacity\Fyyur Project\env\lib\site-packages\sqlalchemy\orm\query.py", line 2768, in all
    return self._iter().all()
  File "C:\Users\1\Desktop\Udacity\Fyyur Project\env\lib\site-packages\sqlalchemy\orm\query.py", line 2903, in _iter
    result = self.session.execute(
  File "C:\Users\1\Desktop\Udacity\Fyyur Project\env\lib\site-packages\sqlalchemy\orm\session.py", line 1695, in execute
    conn = self._connection_for_bind(bind)
  File "C:\Users\1\Desktop\Udacity\Fyyur Project\env\lib\site-packages\sqlalchemy\orm\session.py", line 1536, in _connection_for_bind
    return self._transaction._connection_for_bind(
  File "C:\Users\1\Desktop\Udacity\Fyyur Project\env\lib\site-packages\sqlalchemy\orm\session.py", line 747, in _connection_for_bind
    conn = bind.connect()
  File "C:\Users\1\Desktop\Udacity\Fyyur Project\env\lib\site-packages\sqlalchemy\engine\base.py", line 3234, in connect
    return self._connection_cls(self, close_with_result=close_with_result)
  File "C:\Users\1\Desktop\Udacity\Fyyur Project\env\lib\site-packages\sqlalchemy\engine\base.py", line 96, in __init__
    else engine.raw_connection()
  File "C:\Users\1\Desktop\Udacity\Fyyur Project\env\lib\site-packages\sqlalchemy\engine\base.py", line 3313, in raw_connection
    return self._wrap_pool_connect(self.pool.connect, _connection)
  File "C:\Users\1\Desktop\Udacity\Fyyur Project\env\lib\site-packages\sqlalchemy\engine\base.py", line 3283, in _wrap_pool_connect
    Connection._handle_dbapi_exception_noconnection(
  File "C:\Users\1\Desktop\Udacity\Fyyur Project\env\lib\site-packages\sqlalchemy\engine\base.py", line 2117, in _handle_dbapi_exception_noconnection
    util.raise_(
  File "C:\Users\1\Desktop\Udacity\Fyyur Project\env\lib\site-packages\sqlalchemy\util\compat.py", line 207, in raise_
    raise exception
  File "C:\Users\1\Desktop\Udacity\Fyyur Project\env\lib\site-packages\sqlalchemy\engine\base.py", line 3280, in _wrap_pool_connect
    return fn()
  File "C:\Users\1\Desktop\Udacity\Fyyur Project\env\lib\site-packages\sqlalchemy\pool\base.py", line 310, in connect
    return _ConnectionFairy._checkout(self)
  File "C:\Users\1\Desktop\Udacity\Fyyur Project\env\lib\site-packages\sqlalchemy\pool\base.py", line 868, in _checkout
    fairy = _ConnectionRecord.checkout(pool)
  File "C:\Users\1\Desktop\Udacity\Fyyur Project\env\lib\site-packages\sqlalchemy\pool\base.py", line 476, in checkout
    rec = pool._do_get()
  File "C:\Users\1\Desktop\Udacity\Fyyur Project\env\lib\site-packages\sqlalchemy\pool\impl.py", line 145, in _do_get
    with util.safe_reraise():
  File "C:\Users\1\Desktop\Udacity\Fyyur Project\env\lib\site-packages\sqlalchemy\util\langhelpers.py", line 70, in __exit__
    compat.raise_(
  File "C:\Users\1\Desktop\Udacity\Fyyur Project\env\lib\site-packages\sqlalchemy\util\compat.py", line 207, in raise_
    raise exception
  File "C:\Users\1\Desktop\Udacity\Fyyur Project\env\lib\site-packages\sqlalchemy\pool\impl.py", line 143, in _do_get
    return self._create_connection()
  File "C:\Users\1\Desktop\Udacity\Fyyur Project\env\lib\site-packages\sqlalchemy\pool\base.py", line 256, in _create_connection
    return _ConnectionRecord(self)
  File "C:\Users\1\Desktop\Udacity\Fyyur Project\env\lib\site-packages\sqlalchemy\pool\base.py", line 371, in __init__
    self.__connect()
  File "C:\Users\1\Desktop\Udacity\Fyyur Project\env\lib\site-packages\sqlalchemy\pool\base.py", line 665, in __connect
    with util.safe_reraise():
  File "C:\Users\1\Desktop\Udacity\Fyyur Project\env\lib\site-packages\sqlalchemy\util\langhelpers.py", line 70, in __exit__
    compat.raise_(
  File "C:\Users\1\Desktop\Udacity\Fyyur Project\env\lib\site-packages\sqlalchemy\util\compat.py", line 207, in raise_
    raise exception
  File "C:\Users\1\Desktop\Udacity\Fyyur Project\env\lib\site-packages\sqlalchemy\pool\base.py", line 661, in __connect
    self.dbapi_connection = connection = pool._invoke_creator(self)
  File "C:\Users\1\Desktop\Udacity\Fyyur Project\env\lib\site-packages\sqlalchemy\engine\create.py", line 590, in connect
    return dialect.connect(*cargs, **cparams)
  File "C:\Users\1\Desktop\Udacity\Fyyur Project\env\lib\site-packages\sqlalchemy\engine\default.py", line 597, in connect
    return self.dbapi.connect(*cargs, **cparams)
  File "C:\Users\1\Desktop\Udacity\Fyyur Project\env\lib\site-packages\psycopg2\__init__.py", line 122, in connect
    conn = _connect(dsn, connection_factory=connection_factory, **kwasync)
sqlalchemy.exc.OperationalError: (psycopg2.OperationalError) connection to server at "localhost" (::1), port 5432 failed: FATAL:  database "Fyyur" does not exist

(Background on this error at: https://sqlalche.me/e/14/e3q8)
2022-06-01 12:30:15,007 ERROR: Exception on /favicon.ico [GET] [in C:\Users\1\Desktop\Udacity\Fyyur Project\env\lib\site-packages\flask\app.py:1455]
Traceback (most recent call last):
  File "C:\Users\1\Desktop\Udacity\Fyyur Project\env\lib\site-packages\flask\app.py", line 1523, in full_dispatch_request
    rv = self.dispatch_request()
  File "C:\Users\1\Desktop\Udacity\Fyyur Project\env\lib\site-packages\flask\app.py", line 1499, in dispatch_request
    self.raise_routing_exception(req)
  File "C:\Users\1\Desktop\Udacity\Fyyur Project\env\lib\site-packages\flask\app.py", line 1481, in raise_routing_exception
    raise request.routing_exception  # type: ignore
  File "C:\Users\1\Desktop\Udacity\Fyyur Project\env\lib\site-packages\flask\ctx.py", line 397, in match_request
    result = self.url_adapter.match(return_rule=True)  # type: ignore
  File "C:\Users\1\Desktop\Udacity\Fyyur Project\env\lib\site-packages\werkzeug\routing.py", line 2028, in match
    raise NotFound()
werkzeug.exceptions.NotFound: 404 Not Found: The requested URL was not found on the server. If you entered the URL manually please check your spelling and try again.

During handling of the above exception, another exception occurred:

Traceback (most recent call last):
  File "C:\Users\1\Desktop\Udacity\Fyyur Project\env\lib\site-packages\flask\app.py", line 2077, in wsgi_app
    response = self.full_dispatch_request()
  File "C:\Users\1\Desktop\Udacity\Fyyur Project\env\lib\site-packages\flask\app.py", line 1525, in full_dispatch_request
    rv = self.handle_user_exception(e)
  File "C:\Users\1\Desktop\Udacity\Fyyur Project\env\lib\site-packages\flask\app.py", line 1384, in handle_user_exception
    return self.handle_http_exception(e)
  File "C:\Users\1\Desktop\Udacity\Fyyur Project\env\lib\site-packages\flask\app.py", line 1324, in handle_http_exception
    return self.ensure_sync(handler)(e)
  File "C:\Users\1\Desktop\Udacity\Fyyur Project\app.py", line 713, in not_found_error
    return render_template("errors/404.html"), 404
  File "C:\Users\1\Desktop\Udacity\Fyyur Project\env\lib\site-packages\flask\templating.py", line 148, in render_template
    return _render(
  File "C:\Users\1\Desktop\Udacity\Fyyur Project\env\lib\site-packages\flask\templating.py", line 128, in _render
    rv = template.render(context)
  File "C:\Users\1\Desktop\Udacity\Fyyur Project\env\lib\site-packages\jinja2\environment.py", line 1304, in render
    self.environment.handle_exception()
  File "C:\Users\1\Desktop\Udacity\Fyyur Project\env\lib\site-packages\jinja2\environment.py", line 925, in handle_exception
    raise rewrite_traceback_stack(source=source)
  File "C:\Users\1\Desktop\Udacity\Fyyur Project\templates\errors\404.html", line 1, in <module>
    {% extends 'layouts/main.html' %}
  File "C:\Users\1\Desktop\Udacity\Fyyur Project\templates\layouts\main.html", line 94, in <module>
    <a href="{{ pages/venues.html }}">Venues</a>
  File "C:\Users\1\Desktop\Udacity\Fyyur Project\env\lib\site-packages\jinja2\environment.py", line 474, in getattr
    return getattr(obj, attribute)
jinja2.exceptions.UndefinedError: 'venues' is undefined
2022-06-01 12:31:00,227 INFO: errors [in C:\Users\1\Desktop\Udacity\Fyyur Project\app.py:729]
2022-06-01 12:31:02,873 ERROR: Exception on /artists [GET] [in C:\Users\1\Desktop\Udacity\Fyyur Project\env\lib\site-packages\flask\app.py:1455]
Traceback (most recent call last):
  File "C:\Users\1\Desktop\Udacity\Fyyur Project\env\lib\site-packages\sqlalchemy\engine\base.py", line 3280, in _wrap_pool_connect
    return fn()
  File "C:\Users\1\Desktop\Udacity\Fyyur Project\env\lib\site-packages\sqlalchemy\pool\base.py", line 310, in connect
    return _ConnectionFairy._checkout(self)
  File "C:\Users\1\Desktop\Udacity\Fyyur Project\env\lib\site-packages\sqlalchemy\pool\base.py", line 868, in _checkout
    fairy = _ConnectionRecord.checkout(pool)
  File "C:\Users\1\Desktop\Udacity\Fyyur Project\env\lib\site-packages\sqlalchemy\pool\base.py", line 476, in checkout
    rec = pool._do_get()
  File "C:\Users\1\Desktop\Udacity\Fyyur Project\env\lib\site-packages\sqlalchemy\pool\impl.py", line 145, in _do_get
    with util.safe_reraise():
  File "C:\Users\1\Desktop\Udacity\Fyyur Project\env\lib\site-packages\sqlalchemy\util\langhelpers.py", line 70, in __exit__
    compat.raise_(
  File "C:\Users\1\Desktop\Udacity\Fyyur Project\env\lib\site-packages\sqlalchemy\util\compat.py", line 207, in raise_
    raise exception
  File "C:\Users\1\Desktop\Udacity\Fyyur Project\env\lib\site-packages\sqlalchemy\pool\impl.py", line 143, in _do_get
    return self._create_connection()
  File "C:\Users\1\Desktop\Udacity\Fyyur Project\env\lib\site-packages\sqlalchemy\pool\base.py", line 256, in _create_connection
    return _ConnectionRecord(self)
  File "C:\Users\1\Desktop\Udacity\Fyyur Project\env\lib\site-packages\sqlalchemy\pool\base.py", line 371, in __init__
    self.__connect()
  File "C:\Users\1\Desktop\Udacity\Fyyur Project\env\lib\site-packages\sqlalchemy\pool\base.py", line 665, in __connect
    with util.safe_reraise():
  File "C:\Users\1\Desktop\Udacity\Fyyur Project\env\lib\site-packages\sqlalchemy\util\langhelpers.py", line 70, in __exit__
    compat.raise_(
  File "C:\Users\1\Desktop\Udacity\Fyyur Project\env\lib\site-packages\sqlalchemy\util\compat.py", line 207, in raise_
    raise exception
  File "C:\Users\1\Desktop\Udacity\Fyyur Project\env\lib\site-packages\sqlalchemy\pool\base.py", line 661, in __connect
    self.dbapi_connection = connection = pool._invoke_creator(self)
  File "C:\Users\1\Desktop\Udacity\Fyyur Project\env\lib\site-packages\sqlalchemy\engine\create.py", line 590, in connect
    return dialect.connect(*cargs, **cparams)
  File "C:\Users\1\Desktop\Udacity\Fyyur Project\env\lib\site-packages\sqlalchemy\engine\default.py", line 597, in connect
    return self.dbapi.connect(*cargs, **cparams)
  File "C:\Users\1\Desktop\Udacity\Fyyur Project\env\lib\site-packages\psycopg2\__init__.py", line 122, in connect
    conn = _connect(dsn, connection_factory=connection_factory, **kwasync)
psycopg2.OperationalError: connection to server at "localhost" (::1), port 5432 failed: FATAL:  database "Fyyur" does not exist


The above exception was the direct cause of the following exception:

Traceback (most recent call last):
  File "C:\Users\1\Desktop\Udacity\Fyyur Project\env\lib\site-packages\flask\app.py", line 2077, in wsgi_app
    response = self.full_dispatch_request()
  File "C:\Users\1\Desktop\Udacity\Fyyur Project\env\lib\site-packages\flask\app.py", line 1525, in full_dispatch_request
    rv = self.handle_user_exception(e)
  File "C:\Users\1\Desktop\Udacity\Fyyur Project\env\lib\site-packages\flask\app.py", line 1523, in full_dispatch_request
    rv = self.dispatch_request()
  File "C:\Users\1\Desktop\Udacity\Fyyur Project\env\lib\site-packages\flask\app.py", line 1509, in dispatch_request
    return self.ensure_sync(self.view_functions[rule.endpoint])(**req.view_args)
  File "C:\Users\1\Desktop\Udacity\Fyyur Project\app.py", line 386, in artists
    artists = Artist.query.order_by("id").all()
  File "C:\Users\1\Desktop\Udacity\Fyyur Project\env\lib\site-packages\sqlalchemy\orm\query.py", line 2768, in all
    return self._iter().all()
  File "C:\Users\1\Desktop\Udacity\Fyyur Project\env\lib\site-packages\sqlalchemy\orm\query.py", line 2903, in _iter
    result = self.session.execute(
  File "C:\Users\1\Desktop\Udacity\Fyyur Project\env\lib\site-packages\sqlalchemy\orm\session.py", line 1695, in execute
    conn = self._connection_for_bind(bind)
  File "C:\Users\1\Desktop\Udacity\Fyyur Project\env\lib\site-packages\sqlalchemy\orm\session.py", line 1536, in _connection_for_bind
    return self._transaction._connection_for_bind(
  File "C:\Users\1\Desktop\Udacity\Fyyur Project\env\lib\site-packages\sqlalchemy\orm\session.py", line 747, in _connection_for_bind
    conn = bind.connect()
  File "C:\Users\1\Desktop\Udacity\Fyyur Project\env\lib\site-packages\sqlalchemy\engine\base.py", line 3234, in connect
    return self._connection_cls(self, close_with_result=close_with_result)
  File "C:\Users\1\Desktop\Udacity\Fyyur Project\env\lib\site-packages\sqlalchemy\engine\base.py", line 96, in __init__
    else engine.raw_connection()
  File "C:\Users\1\Desktop\Udacity\Fyyur Project\env\lib\site-packages\sqlalchemy\engine\base.py", line 3313, in raw_connection
    return self._wrap_pool_connect(self.pool.connect, _connection)
  File "C:\Users\1\Desktop\Udacity\Fyyur Project\env\lib\site-packages\sqlalchemy\engine\base.py", line 3283, in _wrap_pool_connect
    Connection._handle_dbapi_exception_noconnection(
  File "C:\Users\1\Desktop\Udacity\Fyyur Project\env\lib\site-packages\sqlalchemy\engine\base.py", line 2117, in _handle_dbapi_exception_noconnection
    util.raise_(
  File "C:\Users\1\Desktop\Udacity\Fyyur Project\env\lib\site-packages\sqlalchemy\util\compat.py", line 207, in raise_
    raise exception
  File "C:\Users\1\Desktop\Udacity\Fyyur Project\env\lib\site-packages\sqlalchemy\engine\base.py", line 3280, in _wrap_pool_connect
    return fn()
  File "C:\Users\1\Desktop\Udacity\Fyyur Project\env\lib\site-packages\sqlalchemy\pool\base.py", line 310, in connect
    return _ConnectionFairy._checkout(self)
  File "C:\Users\1\Desktop\Udacity\Fyyur Project\env\lib\site-packages\sqlalchemy\pool\base.py", line 868, in _checkout
    fairy = _ConnectionRecord.checkout(pool)
  File "C:\Users\1\Desktop\Udacity\Fyyur Project\env\lib\site-packages\sqlalchemy\pool\base.py", line 476, in checkout
    rec = pool._do_get()
  File "C:\Users\1\Desktop\Udacity\Fyyur Project\env\lib\site-packages\sqlalchemy\pool\impl.py", line 145, in _do_get
    with util.safe_reraise():
  File "C:\Users\1\Desktop\Udacity\Fyyur Project\env\lib\site-packages\sqlalchemy\util\langhelpers.py", line 70, in __exit__
    compat.raise_(
  File "C:\Users\1\Desktop\Udacity\Fyyur Project\env\lib\site-packages\sqlalchemy\util\compat.py", line 207, in raise_
    raise exception
  File "C:\Users\1\Desktop\Udacity\Fyyur Project\env\lib\site-packages\sqlalchemy\pool\impl.py", line 143, in _do_get
    return self._create_connection()
  File "C:\Users\1\Desktop\Udacity\Fyyur Project\env\lib\site-packages\sqlalchemy\pool\base.py", line 256, in _create_connection
    return _ConnectionRecord(self)
  File "C:\Users\1\Desktop\Udacity\Fyyur Project\env\lib\site-packages\sqlalchemy\pool\base.py", line 371, in __init__
    self.__connect()
  File "C:\Users\1\Desktop\Udacity\Fyyur Project\env\lib\site-packages\sqlalchemy\pool\base.py", line 665, in __connect
    with util.safe_reraise():
  File "C:\Users\1\Desktop\Udacity\Fyyur Project\env\lib\site-packages\sqlalchemy\util\langhelpers.py", line 70, in __exit__
    compat.raise_(
  File "C:\Users\1\Desktop\Udacity\Fyyur Project\env\lib\site-packages\sqlalchemy\util\compat.py", line 207, in raise_
    raise exception
  File "C:\Users\1\Desktop\Udacity\Fyyur Project\env\lib\site-packages\sqlalchemy\pool\base.py", line 661, in __connect
    self.dbapi_connection = connection = pool._invoke_creator(self)
  File "C:\Users\1\Desktop\Udacity\Fyyur Project\env\lib\site-packages\sqlalchemy\engine\create.py", line 590, in connect
    return dialect.connect(*cargs, **cparams)
  File "C:\Users\1\Desktop\Udacity\Fyyur Project\env\lib\site-packages\sqlalchemy\engine\default.py", line 597, in connect
    return self.dbapi.connect(*cargs, **cparams)
  File "C:\Users\1\Desktop\Udacity\Fyyur Project\env\lib\site-packages\psycopg2\__init__.py", line 122, in connect
    conn = _connect(dsn, connection_factory=connection_factory, **kwasync)
sqlalchemy.exc.OperationalError: (psycopg2.OperationalError) connection to server at "localhost" (::1), port 5432 failed: FATAL:  database "Fyyur" does not exist

(Background on this error at: https://sqlalche.me/e/14/e3q8)
2022-06-01 12:44:13,836 INFO: errors [in C:\Users\1\Desktop\Udacity\Fyyur Project\app.py:729]
2022-06-01 12:44:28,804 ERROR: Exception on /venues [GET] [in C:\Users\1\Desktop\Udacity\Fyyur Project\env\lib\site-packages\flask\app.py:1455]
Traceback (most recent call last):
  File "C:\Users\1\Desktop\Udacity\Fyyur Project\env\lib\site-packages\sqlalchemy\engine\base.py", line 3280, in _wrap_pool_connect
    return fn()
  File "C:\Users\1\Desktop\Udacity\Fyyur Project\env\lib\site-packages\sqlalchemy\pool\base.py", line 310, in connect
    return _ConnectionFairy._checkout(self)
  File "C:\Users\1\Desktop\Udacity\Fyyur Project\env\lib\site-packages\sqlalchemy\pool\base.py", line 868, in _checkout
    fairy = _ConnectionRecord.checkout(pool)
  File "C:\Users\1\Desktop\Udacity\Fyyur Project\env\lib\site-packages\sqlalchemy\pool\base.py", line 476, in checkout
    rec = pool._do_get()
  File "C:\Users\1\Desktop\Udacity\Fyyur Project\env\lib\site-packages\sqlalchemy\pool\impl.py", line 145, in _do_get
    with util.safe_reraise():
  File "C:\Users\1\Desktop\Udacity\Fyyur Project\env\lib\site-packages\sqlalchemy\util\langhelpers.py", line 70, in __exit__
    compat.raise_(
  File "C:\Users\1\Desktop\Udacity\Fyyur Project\env\lib\site-packages\sqlalchemy\util\compat.py", line 207, in raise_
    raise exception
  File "C:\Users\1\Desktop\Udacity\Fyyur Project\env\lib\site-packages\sqlalchemy\pool\impl.py", line 143, in _do_get
    return self._create_connection()
  File "C:\Users\1\Desktop\Udacity\Fyyur Project\env\lib\site-packages\sqlalchemy\pool\base.py", line 256, in _create_connection
    return _ConnectionRecord(self)
  File "C:\Users\1\Desktop\Udacity\Fyyur Project\env\lib\site-packages\sqlalchemy\pool\base.py", line 371, in __init__
    self.__connect()
  File "C:\Users\1\Desktop\Udacity\Fyyur Project\env\lib\site-packages\sqlalchemy\pool\base.py", line 665, in __connect
    with util.safe_reraise():
  File "C:\Users\1\Desktop\Udacity\Fyyur Project\env\lib\site-packages\sqlalchemy\util\langhelpers.py", line 70, in __exit__
    compat.raise_(
  File "C:\Users\1\Desktop\Udacity\Fyyur Project\env\lib\site-packages\sqlalchemy\util\compat.py", line 207, in raise_
    raise exception
  File "C:\Users\1\Desktop\Udacity\Fyyur Project\env\lib\site-packages\sqlalchemy\pool\base.py", line 661, in __connect
    self.dbapi_connection = connection = pool._invoke_creator(self)
  File "C:\Users\1\Desktop\Udacity\Fyyur Project\env\lib\site-packages\sqlalchemy\engine\create.py", line 590, in connect
    return dialect.connect(*cargs, **cparams)
  File "C:\Users\1\Desktop\Udacity\Fyyur Project\env\lib\site-packages\sqlalchemy\engine\default.py", line 597, in connect
    return self.dbapi.connect(*cargs, **cparams)
  File "C:\Users\1\Desktop\Udacity\Fyyur Project\env\lib\site-packages\psycopg2\__init__.py", line 122, in connect
    conn = _connect(dsn, connection_factory=connection_factory, **kwasync)
psycopg2.OperationalError: connection to server at "localhost" (::1), port 5432 failed: FATAL:  database "Fyyur" does not exist


The above exception was the direct cause of the following exception:

Traceback (most recent call last):
  File "C:\Users\1\Desktop\Udacity\Fyyur Project\env\lib\site-packages\flask\app.py", line 2077, in wsgi_app
    response = self.full_dispatch_request()
  File "C:\Users\1\Desktop\Udacity\Fyyur Project\env\lib\site-packages\flask\app.py", line 1525, in full_dispatch_request
    rv = self.handle_user_exception(e)
  File "C:\Users\1\Desktop\Udacity\Fyyur Project\env\lib\site-packages\flask\app.py", line 1523, in full_dispatch_request
    rv = self.dispatch_request()
  File "C:\Users\1\Desktop\Udacity\Fyyur Project\env\lib\site-packages\flask\app.py", line 1509, in dispatch_request
    return self.ensure_sync(self.view_functions[rule.endpoint])(**req.view_args)
  File "C:\Users\1\Desktop\Udacity\Fyyur Project\app.py", line 180, in venues
    .all()
  File "C:\Users\1\Desktop\Udacity\Fyyur Project\env\lib\site-packages\sqlalchemy\orm\query.py", line 2768, in all
    return self._iter().all()
  File "C:\Users\1\Desktop\Udacity\Fyyur Project\env\lib\site-packages\sqlalchemy\orm\query.py", line 2903, in _iter
    result = self.session.execute(
  File "C:\Users\1\Desktop\Udacity\Fyyur Project\env\lib\site-packages\sqlalchemy\orm\session.py", line 1695, in execute
    conn = self._connection_for_bind(bind)
  File "C:\Users\1\Desktop\Udacity\Fyyur Project\env\lib\site-packages\sqlalchemy\orm\session.py", line 1536, in _connection_for_bind
    return self._transaction._connection_for_bind(
  File "C:\Users\1\Desktop\Udacity\Fyyur Project\env\lib\site-packages\sqlalchemy\orm\session.py", line 747, in _connection_for_bind
    conn = bind.connect()
  File "C:\Users\1\Desktop\Udacity\Fyyur Project\env\lib\site-packages\sqlalchemy\engine\base.py", line 3234, in connect
    return self._connection_cls(self, close_with_result=close_with_result)
  File "C:\Users\1\Desktop\Udacity\Fyyur Project\env\lib\site-packages\sqlalchemy\engine\base.py", line 96, in __init__
    else engine.raw_connection()
  File "C:\Users\1\Desktop\Udacity\Fyyur Project\env\lib\site-packages\sqlalchemy\engine\base.py", line 3313, in raw_connection
    return self._wrap_pool_connect(self.pool.connect, _connection)
  File "C:\Users\1\Desktop\Udacity\Fyyur Project\env\lib\site-packages\sqlalchemy\engine\base.py", line 3283, in _wrap_pool_connect
    Connection._handle_dbapi_exception_noconnection(
  File "C:\Users\1\Desktop\Udacity\Fyyur Project\env\lib\site-packages\sqlalchemy\engine\base.py", line 2117, in _handle_dbapi_exception_noconnection
    util.raise_(
  File "C:\Users\1\Desktop\Udacity\Fyyur Project\env\lib\site-packages\sqlalchemy\util\compat.py", line 207, in raise_
    raise exception
  File "C:\Users\1\Desktop\Udacity\Fyyur Project\env\lib\site-packages\sqlalchemy\engine\base.py", line 3280, in _wrap_pool_connect
    return fn()
  File "C:\Users\1\Desktop\Udacity\Fyyur Project\env\lib\site-packages\sqlalchemy\pool\base.py", line 310, in connect
    return _ConnectionFairy._checkout(self)
  File "C:\Users\1\Desktop\Udacity\Fyyur Project\env\lib\site-packages\sqlalchemy\pool\base.py", line 868, in _checkout
    fairy = _ConnectionRecord.checkout(pool)
  File "C:\Users\1\Desktop\Udacity\Fyyur Project\env\lib\site-packages\sqlalchemy\pool\base.py", line 476, in checkout
    rec = pool._do_get()
  File "C:\Users\1\Desktop\Udacity\Fyyur Project\env\lib\site-packages\sqlalchemy\pool\impl.py", line 145, in _do_get
    with util.safe_reraise():
  File "C:\Users\1\Desktop\Udacity\Fyyur Project\env\lib\site-packages\sqlalchemy\util\langhelpers.py", line 70, in __exit__
    compat.raise_(
  File "C:\Users\1\Desktop\Udacity\Fyyur Project\env\lib\site-packages\sqlalchemy\util\compat.py", line 207, in raise_
    raise exception
  File "C:\Users\1\Desktop\Udacity\Fyyur Project\env\lib\site-packages\sqlalchemy\pool\impl.py", line 143, in _do_get
    return self._create_connection()
  File "C:\Users\1\Desktop\Udacity\Fyyur Project\env\lib\site-packages\sqlalchemy\pool\base.py", line 256, in _create_connection
    return _ConnectionRecord(self)
  File "C:\Users\1\Desktop\Udacity\Fyyur Project\env\lib\site-packages\sqlalchemy\pool\base.py", line 371, in __init__
    self.__connect()
  File "C:\Users\1\Desktop\Udacity\Fyyur Project\env\lib\site-packages\sqlalchemy\pool\base.py", line 665, in __connect
    with util.safe_reraise():
  File "C:\Users\1\Desktop\Udacity\Fyyur Project\env\lib\site-packages\sqlalchemy\util\langhelpers.py", line 70, in __exit__
    compat.raise_(
  File "C:\Users\1\Desktop\Udacity\Fyyur Project\env\lib\site-packages\sqlalchemy\util\compat.py", line 207, in raise_
    raise exception
  File "C:\Users\1\Desktop\Udacity\Fyyur Project\env\lib\site-packages\sqlalchemy\pool\base.py", line 661, in __connect
    self.dbapi_connection = connection = pool._invoke_creator(self)
  File "C:\Users\1\Desktop\Udacity\Fyyur Project\env\lib\site-packages\sqlalchemy\engine\create.py", line 590, in connect
    return dialect.connect(*cargs, **cparams)
  File "C:\Users\1\Desktop\Udacity\Fyyur Project\env\lib\site-packages\sqlalchemy\engine\default.py", line 597, in connect
    return self.dbapi.connect(*cargs, **cparams)
  File "C:\Users\1\Desktop\Udacity\Fyyur Project\env\lib\site-packages\psycopg2\__init__.py", line 122, in connect
    conn = _connect(dsn, connection_factory=connection_factory, **kwasync)
sqlalchemy.exc.OperationalError: (psycopg2.OperationalError) connection to server at "localhost" (::1), port 5432 failed: FATAL:  database "Fyyur" does not exist

(Background on this error at: https://sqlalche.me/e/14/e3q8)
2022-06-01 12:44:42,766 ERROR: Exception on /artists [GET] [in C:\Users\1\Desktop\Udacity\Fyyur Project\env\lib\site-packages\flask\app.py:1455]
Traceback (most recent call last):
  File "C:\Users\1\Desktop\Udacity\Fyyur Project\env\lib\site-packages\sqlalchemy\engine\base.py", line 3280, in _wrap_pool_connect
    return fn()
  File "C:\Users\1\Desktop\Udacity\Fyyur Project\env\lib\site-packages\sqlalchemy\pool\base.py", line 310, in connect
    return _ConnectionFairy._checkout(self)
  File "C:\Users\1\Desktop\Udacity\Fyyur Project\env\lib\site-packages\sqlalchemy\pool\base.py", line 868, in _checkout
    fairy = _ConnectionRecord.checkout(pool)
  File "C:\Users\1\Desktop\Udacity\Fyyur Project\env\lib\site-packages\sqlalchemy\pool\base.py", line 476, in checkout
    rec = pool._do_get()
  File "C:\Users\1\Desktop\Udacity\Fyyur Project\env\lib\site-packages\sqlalchemy\pool\impl.py", line 145, in _do_get
    with util.safe_reraise():
  File "C:\Users\1\Desktop\Udacity\Fyyur Project\env\lib\site-packages\sqlalchemy\util\langhelpers.py", line 70, in __exit__
    compat.raise_(
  File "C:\Users\1\Desktop\Udacity\Fyyur Project\env\lib\site-packages\sqlalchemy\util\compat.py", line 207, in raise_
    raise exception
  File "C:\Users\1\Desktop\Udacity\Fyyur Project\env\lib\site-packages\sqlalchemy\pool\impl.py", line 143, in _do_get
    return self._create_connection()
  File "C:\Users\1\Desktop\Udacity\Fyyur Project\env\lib\site-packages\sqlalchemy\pool\base.py", line 256, in _create_connection
    return _ConnectionRecord(self)
  File "C:\Users\1\Desktop\Udacity\Fyyur Project\env\lib\site-packages\sqlalchemy\pool\base.py", line 371, in __init__
    self.__connect()
  File "C:\Users\1\Desktop\Udacity\Fyyur Project\env\lib\site-packages\sqlalchemy\pool\base.py", line 665, in __connect
    with util.safe_reraise():
  File "C:\Users\1\Desktop\Udacity\Fyyur Project\env\lib\site-packages\sqlalchemy\util\langhelpers.py", line 70, in __exit__
    compat.raise_(
  File "C:\Users\1\Desktop\Udacity\Fyyur Project\env\lib\site-packages\sqlalchemy\util\compat.py", line 207, in raise_
    raise exception
  File "C:\Users\1\Desktop\Udacity\Fyyur Project\env\lib\site-packages\sqlalchemy\pool\base.py", line 661, in __connect
    self.dbapi_connection = connection = pool._invoke_creator(self)
  File "C:\Users\1\Desktop\Udacity\Fyyur Project\env\lib\site-packages\sqlalchemy\engine\create.py", line 590, in connect
    return dialect.connect(*cargs, **cparams)
  File "C:\Users\1\Desktop\Udacity\Fyyur Project\env\lib\site-packages\sqlalchemy\engine\default.py", line 597, in connect
    return self.dbapi.connect(*cargs, **cparams)
  File "C:\Users\1\Desktop\Udacity\Fyyur Project\env\lib\site-packages\psycopg2\__init__.py", line 122, in connect
    conn = _connect(dsn, connection_factory=connection_factory, **kwasync)
psycopg2.OperationalError: connection to server at "localhost" (::1), port 5432 failed: FATAL:  database "Fyyur" does not exist


The above exception was the direct cause of the following exception:

Traceback (most recent call last):
  File "C:\Users\1\Desktop\Udacity\Fyyur Project\env\lib\site-packages\flask\app.py", line 2077, in wsgi_app
    response = self.full_dispatch_request()
  File "C:\Users\1\Desktop\Udacity\Fyyur Project\env\lib\site-packages\flask\app.py", line 1525, in full_dispatch_request
    rv = self.handle_user_exception(e)
  File "C:\Users\1\Desktop\Udacity\Fyyur Project\env\lib\site-packages\flask\app.py", line 1523, in full_dispatch_request
    rv = self.dispatch_request()
  File "C:\Users\1\Desktop\Udacity\Fyyur Project\env\lib\site-packages\flask\app.py", line 1509, in dispatch_request
    return self.ensure_sync(self.view_functions[rule.endpoint])(**req.view_args)
  File "C:\Users\1\Desktop\Udacity\Fyyur Project\app.py", line 386, in artists
    artists = Artist.query.order_by("id").all()
  File "C:\Users\1\Desktop\Udacity\Fyyur Project\env\lib\site-packages\sqlalchemy\orm\query.py", line 2768, in all
    return self._iter().all()
  File "C:\Users\1\Desktop\Udacity\Fyyur Project\env\lib\site-packages\sqlalchemy\orm\query.py", line 2903, in _iter
    result = self.session.execute(
  File "C:\Users\1\Desktop\Udacity\Fyyur Project\env\lib\site-packages\sqlalchemy\orm\session.py", line 1695, in execute
    conn = self._connection_for_bind(bind)
  File "C:\Users\1\Desktop\Udacity\Fyyur Project\env\lib\site-packages\sqlalchemy\orm\session.py", line 1536, in _connection_for_bind
    return self._transaction._connection_for_bind(
  File "C:\Users\1\Desktop\Udacity\Fyyur Project\env\lib\site-packages\sqlalchemy\orm\session.py", line 747, in _connection_for_bind
    conn = bind.connect()
  File "C:\Users\1\Desktop\Udacity\Fyyur Project\env\lib\site-packages\sqlalchemy\engine\base.py", line 3234, in connect
    return self._connection_cls(self, close_with_result=close_with_result)
  File "C:\Users\1\Desktop\Udacity\Fyyur Project\env\lib\site-packages\sqlalchemy\engine\base.py", line 96, in __init__
    else engine.raw_connection()
  File "C:\Users\1\Desktop\Udacity\Fyyur Project\env\lib\site-packages\sqlalchemy\engine\base.py", line 3313, in raw_connection
    return self._wrap_pool_connect(self.pool.connect, _connection)
  File "C:\Users\1\Desktop\Udacity\Fyyur Project\env\lib\site-packages\sqlalchemy\engine\base.py", line 3283, in _wrap_pool_connect
    Connection._handle_dbapi_exception_noconnection(
  File "C:\Users\1\Desktop\Udacity\Fyyur Project\env\lib\site-packages\sqlalchemy\engine\base.py", line 2117, in _handle_dbapi_exception_noconnection
    util.raise_(
  File "C:\Users\1\Desktop\Udacity\Fyyur Project\env\lib\site-packages\sqlalchemy\util\compat.py", line 207, in raise_
    raise exception
  File "C:\Users\1\Desktop\Udacity\Fyyur Project\env\lib\site-packages\sqlalchemy\engine\base.py", line 3280, in _wrap_pool_connect
    return fn()
  File "C:\Users\1\Desktop\Udacity\Fyyur Project\env\lib\site-packages\sqlalchemy\pool\base.py", line 310, in connect
    return _ConnectionFairy._checkout(self)
  File "C:\Users\1\Desktop\Udacity\Fyyur Project\env\lib\site-packages\sqlalchemy\pool\base.py", line 868, in _checkout
    fairy = _ConnectionRecord.checkout(pool)
  File "C:\Users\1\Desktop\Udacity\Fyyur Project\env\lib\site-packages\sqlalchemy\pool\base.py", line 476, in checkout
    rec = pool._do_get()
  File "C:\Users\1\Desktop\Udacity\Fyyur Project\env\lib\site-packages\sqlalchemy\pool\impl.py", line 145, in _do_get
    with util.safe_reraise():
  File "C:\Users\1\Desktop\Udacity\Fyyur Project\env\lib\site-packages\sqlalchemy\util\langhelpers.py", line 70, in __exit__
    compat.raise_(
  File "C:\Users\1\Desktop\Udacity\Fyyur Project\env\lib\site-packages\sqlalchemy\util\compat.py", line 207, in raise_
    raise exception
  File "C:\Users\1\Desktop\Udacity\Fyyur Project\env\lib\site-packages\sqlalchemy\pool\impl.py", line 143, in _do_get
    return self._create_connection()
  File "C:\Users\1\Desktop\Udacity\Fyyur Project\env\lib\site-packages\sqlalchemy\pool\base.py", line 256, in _create_connection
    return _ConnectionRecord(self)
  File "C:\Users\1\Desktop\Udacity\Fyyur Project\env\lib\site-packages\sqlalchemy\pool\base.py", line 371, in __init__
    self.__connect()
  File "C:\Users\1\Desktop\Udacity\Fyyur Project\env\lib\site-packages\sqlalchemy\pool\base.py", line 665, in __connect
    with util.safe_reraise():
  File "C:\Users\1\Desktop\Udacity\Fyyur Project\env\lib\site-packages\sqlalchemy\util\langhelpers.py", line 70, in __exit__
    compat.raise_(
  File "C:\Users\1\Desktop\Udacity\Fyyur Project\env\lib\site-packages\sqlalchemy\util\compat.py", line 207, in raise_
    raise exception
  File "C:\Users\1\Desktop\Udacity\Fyyur Project\env\lib\site-packages\sqlalchemy\pool\base.py", line 661, in __connect
    self.dbapi_connection = connection = pool._invoke_creator(self)
  File "C:\Users\1\Desktop\Udacity\Fyyur Project\env\lib\site-packages\sqlalchemy\engine\create.py", line 590, in connect
    return dialect.connect(*cargs, **cparams)
  File "C:\Users\1\Desktop\Udacity\Fyyur Project\env\lib\site-packages\sqlalchemy\engine\default.py", line 597, in connect
    return self.dbapi.connect(*cargs, **cparams)
  File "C:\Users\1\Desktop\Udacity\Fyyur Project\env\lib\site-packages\psycopg2\__init__.py", line 122, in connect
    conn = _connect(dsn, connection_factory=connection_factory, **kwasync)
sqlalchemy.exc.OperationalError: (psycopg2.OperationalError) connection to server at "localhost" (::1), port 5432 failed: FATAL:  database "Fyyur" does not exist

(Background on this error at: https://sqlalche.me/e/14/e3q8)
2022-06-01 12:44:51,477 ERROR: Exception on /shows [GET] [in C:\Users\1\Desktop\Udacity\Fyyur Project\env\lib\site-packages\flask\app.py:1455]
Traceback (most recent call last):
  File "C:\Users\1\Desktop\Udacity\Fyyur Project\env\lib\site-packages\sqlalchemy\engine\base.py", line 3280, in _wrap_pool_connect
    return fn()
  File "C:\Users\1\Desktop\Udacity\Fyyur Project\env\lib\site-packages\sqlalchemy\pool\base.py", line 310, in connect
    return _ConnectionFairy._checkout(self)
  File "C:\Users\1\Desktop\Udacity\Fyyur Project\env\lib\site-packages\sqlalchemy\pool\base.py", line 868, in _checkout
    fairy = _ConnectionRecord.checkout(pool)
  File "C:\Users\1\Desktop\Udacity\Fyyur Project\env\lib\site-packages\sqlalchemy\pool\base.py", line 476, in checkout
    rec = pool._do_get()
  File "C:\Users\1\Desktop\Udacity\Fyyur Project\env\lib\site-packages\sqlalchemy\pool\impl.py", line 145, in _do_get
    with util.safe_reraise():
  File "C:\Users\1\Desktop\Udacity\Fyyur Project\env\lib\site-packages\sqlalchemy\util\langhelpers.py", line 70, in __exit__
    compat.raise_(
  File "C:\Users\1\Desktop\Udacity\Fyyur Project\env\lib\site-packages\sqlalchemy\util\compat.py", line 207, in raise_
    raise exception
  File "C:\Users\1\Desktop\Udacity\Fyyur Project\env\lib\site-packages\sqlalchemy\pool\impl.py", line 143, in _do_get
    return self._create_connection()
  File "C:\Users\1\Desktop\Udacity\Fyyur Project\env\lib\site-packages\sqlalchemy\pool\base.py", line 256, in _create_connection
    return _ConnectionRecord(self)
  File "C:\Users\1\Desktop\Udacity\Fyyur Project\env\lib\site-packages\sqlalchemy\pool\base.py", line 371, in __init__
    self.__connect()
  File "C:\Users\1\Desktop\Udacity\Fyyur Project\env\lib\site-packages\sqlalchemy\pool\base.py", line 665, in __connect
    with util.safe_reraise():
  File "C:\Users\1\Desktop\Udacity\Fyyur Project\env\lib\site-packages\sqlalchemy\util\langhelpers.py", line 70, in __exit__
    compat.raise_(
  File "C:\Users\1\Desktop\Udacity\Fyyur Project\env\lib\site-packages\sqlalchemy\util\compat.py", line 207, in raise_
    raise exception
  File "C:\Users\1\Desktop\Udacity\Fyyur Project\env\lib\site-packages\sqlalchemy\pool\base.py", line 661, in __connect
    self.dbapi_connection = connection = pool._invoke_creator(self)
  File "C:\Users\1\Desktop\Udacity\Fyyur Project\env\lib\site-packages\sqlalchemy\engine\create.py", line 590, in connect
    return dialect.connect(*cargs, **cparams)
  File "C:\Users\1\Desktop\Udacity\Fyyur Project\env\lib\site-packages\sqlalchemy\engine\default.py", line 597, in connect
    return self.dbapi.connect(*cargs, **cparams)
  File "C:\Users\1\Desktop\Udacity\Fyyur Project\env\lib\site-packages\psycopg2\__init__.py", line 122, in connect
    conn = _connect(dsn, connection_factory=connection_factory, **kwasync)
psycopg2.OperationalError: connection to server at "localhost" (::1), port 5432 failed: FATAL:  database "Fyyur" does not exist


The above exception was the direct cause of the following exception:

Traceback (most recent call last):
  File "C:\Users\1\Desktop\Udacity\Fyyur Project\env\lib\site-packages\flask\app.py", line 2077, in wsgi_app
    response = self.full_dispatch_request()
  File "C:\Users\1\Desktop\Udacity\Fyyur Project\env\lib\site-packages\flask\app.py", line 1525, in full_dispatch_request
    rv = self.handle_user_exception(e)
  File "C:\Users\1\Desktop\Udacity\Fyyur Project\env\lib\site-packages\flask\app.py", line 1523, in full_dispatch_request
    rv = self.dispatch_request()
  File "C:\Users\1\Desktop\Udacity\Fyyur Project\env\lib\site-packages\flask\app.py", line 1509, in dispatch_request
    return self.ensure_sync(self.view_functions[rule.endpoint])(**req.view_args)
  File "C:\Users\1\Desktop\Udacity\Fyyur Project\app.py", line 665, in shows
    for show in db.session.query(Show).join(Artist).join(Venue).all():
  File "C:\Users\1\Desktop\Udacity\Fyyur Project\env\lib\site-packages\sqlalchemy\orm\query.py", line 2768, in all
    return self._iter().all()
  File "C:\Users\1\Desktop\Udacity\Fyyur Project\env\lib\site-packages\sqlalchemy\orm\query.py", line 2903, in _iter
    result = self.session.execute(
  File "C:\Users\1\Desktop\Udacity\Fyyur Project\env\lib\site-packages\sqlalchemy\orm\session.py", line 1695, in execute
    conn = self._connection_for_bind(bind)
  File "C:\Users\1\Desktop\Udacity\Fyyur Project\env\lib\site-packages\sqlalchemy\orm\session.py", line 1536, in _connection_for_bind
    return self._transaction._connection_for_bind(
  File "C:\Users\1\Desktop\Udacity\Fyyur Project\env\lib\site-packages\sqlalchemy\orm\session.py", line 747, in _connection_for_bind
    conn = bind.connect()
  File "C:\Users\1\Desktop\Udacity\Fyyur Project\env\lib\site-packages\sqlalchemy\engine\base.py", line 3234, in connect
    return self._connection_cls(self, close_with_result=close_with_result)
  File "C:\Users\1\Desktop\Udacity\Fyyur Project\env\lib\site-packages\sqlalchemy\engine\base.py", line 96, in __init__
    else engine.raw_connection()
  File "C:\Users\1\Desktop\Udacity\Fyyur Project\env\lib\site-packages\sqlalchemy\engine\base.py", line 3313, in raw_connection
    return self._wrap_pool_connect(self.pool.connect, _connection)
  File "C:\Users\1\Desktop\Udacity\Fyyur Project\env\lib\site-packages\sqlalchemy\engine\base.py", line 3283, in _wrap_pool_connect
    Connection._handle_dbapi_exception_noconnection(
  File "C:\Users\1\Desktop\Udacity\Fyyur Project\env\lib\site-packages\sqlalchemy\engine\base.py", line 2117, in _handle_dbapi_exception_noconnection
    util.raise_(
  File "C:\Users\1\Desktop\Udacity\Fyyur Project\env\lib\site-packages\sqlalchemy\util\compat.py", line 207, in raise_
    raise exception
  File "C:\Users\1\Desktop\Udacity\Fyyur Project\env\lib\site-packages\sqlalchemy\engine\base.py", line 3280, in _wrap_pool_connect
    return fn()
  File "C:\Users\1\Desktop\Udacity\Fyyur Project\env\lib\site-packages\sqlalchemy\pool\base.py", line 310, in connect
    return _ConnectionFairy._checkout(self)
  File "C:\Users\1\Desktop\Udacity\Fyyur Project\env\lib\site-packages\sqlalchemy\pool\base.py", line 868, in _checkout
    fairy = _ConnectionRecord.checkout(pool)
  File "C:\Users\1\Desktop\Udacity\Fyyur Project\env\lib\site-packages\sqlalchemy\pool\base.py", line 476, in checkout
    rec = pool._do_get()
  File "C:\Users\1\Desktop\Udacity\Fyyur Project\env\lib\site-packages\sqlalchemy\pool\impl.py", line 145, in _do_get
    with util.safe_reraise():
  File "C:\Users\1\Desktop\Udacity\Fyyur Project\env\lib\site-packages\sqlalchemy\util\langhelpers.py", line 70, in __exit__
    compat.raise_(
  File "C:\Users\1\Desktop\Udacity\Fyyur Project\env\lib\site-packages\sqlalchemy\util\compat.py", line 207, in raise_
    raise exception
  File "C:\Users\1\Desktop\Udacity\Fyyur Project\env\lib\site-packages\sqlalchemy\pool\impl.py", line 143, in _do_get
    return self._create_connection()
  File "C:\Users\1\Desktop\Udacity\Fyyur Project\env\lib\site-packages\sqlalchemy\pool\base.py", line 256, in _create_connection
    return _ConnectionRecord(self)
  File "C:\Users\1\Desktop\Udacity\Fyyur Project\env\lib\site-packages\sqlalchemy\pool\base.py", line 371, in __init__
    self.__connect()
  File "C:\Users\1\Desktop\Udacity\Fyyur Project\env\lib\site-packages\sqlalchemy\pool\base.py", line 665, in __connect
    with util.safe_reraise():
  File "C:\Users\1\Desktop\Udacity\Fyyur Project\env\lib\site-packages\sqlalchemy\util\langhelpers.py", line 70, in __exit__
    compat.raise_(
  File "C:\Users\1\Desktop\Udacity\Fyyur Project\env\lib\site-packages\sqlalchemy\util\compat.py", line 207, in raise_
    raise exception
  File "C:\Users\1\Desktop\Udacity\Fyyur Project\env\lib\site-packages\sqlalchemy\pool\base.py", line 661, in __connect
    self.dbapi_connection = connection = pool._invoke_creator(self)
  File "C:\Users\1\Desktop\Udacity\Fyyur Project\env\lib\site-packages\sqlalchemy\engine\create.py", line 590, in connect
    return dialect.connect(*cargs, **cparams)
  File "C:\Users\1\Desktop\Udacity\Fyyur Project\env\lib\site-packages\sqlalchemy\engine\default.py", line 597, in connect
    return self.dbapi.connect(*cargs, **cparams)
  File "C:\Users\1\Desktop\Udacity\Fyyur Project\env\lib\site-packages\psycopg2\__init__.py", line 122, in connect
    conn = _connect(dsn, connection_factory=connection_factory, **kwasync)
sqlalchemy.exc.OperationalError: (psycopg2.OperationalError) connection to server at "localhost" (::1), port 5432 failed: FATAL:  database "Fyyur" does not exist

(Background on this error at: https://sqlalche.me/e/14/e3q8)
2022-06-01 12:47:25,597 INFO: errors [in C:\Users\1\Desktop\Udacity\Fyyur Project\app.py:729]
2022-06-01 12:51:26,091 INFO: errors [in C:\Users\1\Desktop\Udacity\Fyyur Project\app.py:729]
2022-06-01 12:57:51,959 INFO: errors [in C:\Users\1\Desktop\Udacity\Fyyur Project\app.py:729]
2022-06-01 12:57:54,235 ERROR: Exception on / [GET] [in C:\Users\1\Desktop\Udacity\Fyyur Project\env\lib\site-packages\flask\app.py:1455]
Traceback (most recent call last):
  File "C:\Users\1\Desktop\Udacity\Fyyur Project\env\lib\site-packages\flask\app.py", line 2077, in wsgi_app
    response = self.full_dispatch_request()
  File "C:\Users\1\Desktop\Udacity\Fyyur Project\env\lib\site-packages\flask\app.py", line 1525, in full_dispatch_request
    rv = self.handle_user_exception(e)
  File "C:\Users\1\Desktop\Udacity\Fyyur Project\env\lib\site-packages\flask\app.py", line 1523, in full_dispatch_request
    rv = self.dispatch_request()
  File "C:\Users\1\Desktop\Udacity\Fyyur Project\env\lib\site-packages\flask\app.py", line 1509, in dispatch_request
    return self.ensure_sync(self.view_functions[rule.endpoint])(**req.view_args)
  File "C:\Users\1\Desktop\Udacity\Fyyur Project\app.py", line 166, in index
    return render_template("pages/home.html")
  File "C:\Users\1\Desktop\Udacity\Fyyur Project\env\lib\site-packages\flask\templating.py", line 148, in render_template
    return _render(
  File "C:\Users\1\Desktop\Udacity\Fyyur Project\env\lib\site-packages\flask\templating.py", line 128, in _render
    rv = template.render(context)
  File "C:\Users\1\Desktop\Udacity\Fyyur Project\env\lib\site-packages\jinja2\environment.py", line 1304, in render
    self.environment.handle_exception()
  File "C:\Users\1\Desktop\Udacity\Fyyur Project\env\lib\site-packages\jinja2\environment.py", line 925, in handle_exception
    raise rewrite_traceback_stack(source=source)
  File "C:\Users\1\Desktop\Udacity\Fyyur Project\templates\pages\home.html", line 1, in <module>
    {% extends 'layouts/main.html' %}
  File "C:\Users\1\Desktop\Udacity\Fyyur Project\templates\layouts\main.html", line 94, in <module>
    <a href="/venues/{{ venue.id }}">Venues</a>
  File "C:\Users\1\Desktop\Udacity\Fyyur Project\env\lib\site-packages\jinja2\environment.py", line 474, in getattr
    return getattr(obj, attribute)
jinja2.exceptions.UndefinedError: 'venue' is undefined
2022-06-01 12:57:54,557 ERROR: Exception on /favicon.ico [GET] [in C:\Users\1\Desktop\Udacity\Fyyur Project\env\lib\site-packages\flask\app.py:1455]
Traceback (most recent call last):
  File "C:\Users\1\Desktop\Udacity\Fyyur Project\env\lib\site-packages\flask\app.py", line 1523, in full_dispatch_request
    rv = self.dispatch_request()
  File "C:\Users\1\Desktop\Udacity\Fyyur Project\env\lib\site-packages\flask\app.py", line 1499, in dispatch_request
    self.raise_routing_exception(req)
  File "C:\Users\1\Desktop\Udacity\Fyyur Project\env\lib\site-packages\flask\app.py", line 1481, in raise_routing_exception
    raise request.routing_exception  # type: ignore
  File "C:\Users\1\Desktop\Udacity\Fyyur Project\env\lib\site-packages\flask\ctx.py", line 397, in match_request
    result = self.url_adapter.match(return_rule=True)  # type: ignore
  File "C:\Users\1\Desktop\Udacity\Fyyur Project\env\lib\site-packages\werkzeug\routing.py", line 2028, in match
    raise NotFound()
werkzeug.exceptions.NotFound: 404 Not Found: The requested URL was not found on the server. If you entered the URL manually please check your spelling and try again.

During handling of the above exception, another exception occurred:

Traceback (most recent call last):
  File "C:\Users\1\Desktop\Udacity\Fyyur Project\env\lib\site-packages\flask\app.py", line 2077, in wsgi_app
    response = self.full_dispatch_request()
  File "C:\Users\1\Desktop\Udacity\Fyyur Project\env\lib\site-packages\flask\app.py", line 1525, in full_dispatch_request
    rv = self.handle_user_exception(e)
  File "C:\Users\1\Desktop\Udacity\Fyyur Project\env\lib\site-packages\flask\app.py", line 1384, in handle_user_exception
    return self.handle_http_exception(e)
  File "C:\Users\1\Desktop\Udacity\Fyyur Project\env\lib\site-packages\flask\app.py", line 1324, in handle_http_exception
    return self.ensure_sync(handler)(e)
  File "C:\Users\1\Desktop\Udacity\Fyyur Project\app.py", line 713, in not_found_error
    return render_template("errors/404.html"), 404
  File "C:\Users\1\Desktop\Udacity\Fyyur Project\env\lib\site-packages\flask\templating.py", line 148, in render_template
    return _render(
  File "C:\Users\1\Desktop\Udacity\Fyyur Project\env\lib\site-packages\flask\templating.py", line 128, in _render
    rv = template.render(context)
  File "C:\Users\1\Desktop\Udacity\Fyyur Project\env\lib\site-packages\jinja2\environment.py", line 1304, in render
    self.environment.handle_exception()
  File "C:\Users\1\Desktop\Udacity\Fyyur Project\env\lib\site-packages\jinja2\environment.py", line 925, in handle_exception
    raise rewrite_traceback_stack(source=source)
  File "C:\Users\1\Desktop\Udacity\Fyyur Project\templates\errors\404.html", line 1, in <module>
    {% extends 'layouts/main.html' %}
  File "C:\Users\1\Desktop\Udacity\Fyyur Project\templates\layouts\main.html", line 94, in <module>
    <a href="/venues/{{ venue.id }}">Venues</a>
  File "C:\Users\1\Desktop\Udacity\Fyyur Project\env\lib\site-packages\jinja2\environment.py", line 474, in getattr
    return getattr(obj, attribute)
jinja2.exceptions.UndefinedError: 'venue' is undefined
